<?xml version='1.0' encoding='UTF-8'?>
<robot name="bipedal_robot">
  <mujoco>
    <compiler meshdir="../meshes"/>
  </mujoco>

  <!-- base -->
  <link name="base_Link">
    <inertial>
      <origin xyz="0.00385 -0.00011 0.11254" rpy="0.0 0.0 0.0"/>
      <mass value="12.57"/>
      <inertia ixx="0.11473868" ixy="-1.726e-05" ixz="0.00717502" iyy="0.13581253" iyz="8.123e-05" izz="0.10540873"/>
    </inertial>
    <visual>
      <geometry>
        <mesh filename="package://bipedal_robot/meshes/base_Link.STL"/>
      </geometry>
      <material name="grey">
        <color rgba="1 1 1 1"/>
      </material>
    </visual>
    <collision>
      <geometry>
        <mesh filename="package://bipedal_robot/meshes/base_Link.STL"/>
      </geometry>
    </collision>
  </link>

  <!-- base imu -->
  <link name="base_imu">
    <inertial>
      <origin xyz="0.0 0.0 0.0" rpy="0.0 0.0 0.0"/>
      <mass value="0.01"/>
      <inertia ixx="1e-06" ixy="0.0" ixz="0.0" iyy="1e-06" iyz="0.0" izz="1e-06"/>
    </inertial>
  </link>
  <joint name="base_imu_Joint" type="fixed">
    <origin xyz="0.0 0.0 0.0" rpy="0.0 0.0 0.0"/>
    <parent link="base_Link"/>
    <child link="base_imu"/>
  </joint>

  <!-- proximal pitch L Link -->
  <link name="proximal_pitch_L_Link">
    <inertial>
      <origin xyz="-0.00547 0.07014 -0.00611" rpy="0.0 0.0 0.0"/>
      <mass value="2.21"/>
      <inertia ixx="0.00438539" ixy="-1.065e-05" ixz="1.817e-05" iyy="0.00308183" iyz="5.213e-05" izz="0.00349504"/>
    </inertial>
    <visual>
      <geometry>
        <mesh filename="package://bipedal_robot/meshes/proximal_pitch_L_Link.STL"/>
      </geometry>
      <material name="grey">
        <color rgba="1 1 1 1"/>
      </material>
    </visual>
    <collision>
      <geometry>
        <mesh filename="package://bipedal_robot/meshes/proximal_pitch_L_Link.STL"/>
      </geometry>
    </collision>
  </link>
  <joint name="proximal_pitch_L_Joint" type="revolute">
    <origin xyz="-0.00044 0.09178 0.05474" rpy="0.0 0.0 0.0"/>
    <parent link="base_Link"/>
    <child link="proximal_pitch_L_Link"/>
    <axis xyz="0.0 0.9961947268929313 -0.0871554135479712"/>
    <limit lower="-3.141592653589793" upper="2.600540585471551" effort="150.0" velocity="18.3"/>
  </joint>
  <link name="proximal_roll_L_Link">
    <inertial>
      <origin xyz="0.03124 0.00035 -0.08414" rpy="0.0 0.0 0.0"/>
      <mass value="1.74"/>
      <inertia ixx="0.00476933" ixy="-1.172e-05" ixz="3.271e-05" iyy="0.00545584" iyz="-2.946e-05" izz="0.00305316"/>
    </inertial>
    <visual>
      <geometry>
        <mesh filename="package://bipedal_robot/meshes/proximal_roll_L_Link.STL"/>
      </geometry>
      <material name="grey">
        <color rgba="1 1 1 1"/>
      </material>
    </visual>
    <collision>
      <geometry>
        <mesh filename="package://bipedal_robot/meshes/proximal_roll_L_Link.STL"/>
      </geometry>
    </collision>
  </link>
  <joint name="proximal_roll_L_Joint" type="revolute">
    <origin xyz="-0.032 0.0758 -0.00663" rpy="0.0 0.0 0.0"/>
    <parent link="proximal_pitch_L_Link"/>
    <child link="proximal_roll_L_Link"/>
    <axis xyz="1.0 0.0 0.0"/>
    <limit lower="-0.2617993877991494" upper="3.193952531149623" effort="150.0" velocity="18.3"/>
  </joint>
  <link name="proximal_yaw_L_Link">
    <inertial>
      <origin xyz="-0.00254 0.00155 -0.10742" rpy="0.0 0.0 0.0"/>
      <mass value="1.65"/>
      <inertia ixx="0.01554314" ixy="-3.32e-06" ixz="0.00024639" iyy="0.01485362" iyz="7.569e-05" izz="0.00378004"/>
    </inertial>
    <visual>
      <geometry>
        <mesh filename="package://bipedal_robot/meshes/proximal_yaw_L_Link.STL"/>
      </geometry>
      <material name="grey">
        <color rgba="1 1 1 1"/>
      </material>
    </visual>
    <collision>
      <geometry>
        <mesh filename="package://bipedal_robot/meshes/proximal_yaw_L_Link.STL"/>
      </geometry>
    </collision>
  </link>
  <joint name="proximal_yaw_L_Joint" type="revolute">
    <origin xyz="0.032 0.0 -0.1374" rpy="0.0 0.0 0.0"/>
    <parent link="proximal_roll_L_Link"/>
    <child link="proximal_yaw_L_Link"/>
    <axis xyz="0.0 0.0 1.0"/>
    <limit lower="-3.6651914291880923" upper="1.4835298641951802" effort="60.0" velocity="22.52"/>
  </joint>
  <link name="knee_L_Link">
    <inertial>
      <origin xyz="-0.00204 -0.02449 -0.12995" rpy="0.0 0.0 0.0"/>
      <mass value="4.66"/>
      <inertia ixx="0.11057056" ixy="7.11e-06" ixz="-0.0010003" iyy="0.11286353" iyz="0.00158987" izz="0.00620343"/>
    </inertial>
    <visual>
      <geometry>
        <mesh filename="package://bipedal_robot/meshes/knee_L_Link.STL"/>
      </geometry>
      <material name="grey">
        <color rgba="1 1 1 1"/>
      </material>
    </visual>
    <collision>
      <geometry>
        <mesh filename="package://bipedal_robot/meshes/knee_L_Link.STL"/>
      </geometry>
    </collision>
  </link>
  <joint name="knee_L_Joint" type="revolute">
    <origin xyz="0.004 0.032 -0.2126" rpy="0.0 0.0 0.0"/>
    <parent link="proximal_yaw_L_Link"/>
    <child link="knee_L_Link"/>
    <axis xyz="0.0 1.0 0.0"/>
    <limit lower="-2.6179938779914944" upper="0.2617993877991494" effort="150.0" velocity="18.3"/>
  </joint>
  <link name="wheel_L_Link">
    <inertial>
      <origin xyz="0.00048 0.00484 0.0003" rpy="0.0 0.0 0.0"/>
      <mass value="0.91"/>
      <inertia ixx="0.00256223" ixy="7.6e-07" ixz="-2.292e-05" iyy="0.00490844" iyz="4.2e-07" izz="0.00259234"/>
    </inertial>
    <visual>
      <geometry>
        <mesh filename="package://bipedal_robot/meshes/wheel_L_Link.STL"/>
      </geometry>
      <material name="grey">
        <color rgba="1 1 1 1"/>
      </material>
    </visual>
    <collision>
      <origin rpy="1.5707963267948966 0 0" xyz="0 0.003 0"/>
      <geometry>
          <cylinder length="0.045" radius="0.1"/>
      </geometry>
    </collision>
  </link>
  <joint name="wheel_L_Joint" type="revolute">
    <origin xyz="-0.004 0.013 -0.35" rpy="0.0 0.0 0.0"/>
    <parent link="knee_L_Link"/>
    <child link="wheel_L_Link"/>
    <axis xyz="0.0 1.0 0.0"/>
    <limit lower="-1745329.2519943295" upper="1745329.2519943295" effort="22.0" velocity="41.89"/>
  </joint>

  <!-- proximal pitch R Link -->
  <link name="proximal_pitch_R_Link">
    <inertial>
      <origin xyz="-0.00547 -0.07014 -0.00611" rpy="-0.0 0.0 -0.0"/>
      <mass value="2.21"/>
      <inertia ixx="0.00438539" ixy="1.065e-05" ixz="1.817e-05" iyy="0.00308183" iyz="-5.213e-05" izz="0.00349504"/>
    </inertial>
    <visual>
      <geometry>
        <mesh filename="package://bipedal_robot/meshes/proximal_pitch_R_Link.STL"/>
      </geometry>
      <material name="grey">
        <color rgba="1 1 1 1"/>
      </material>
    </visual>
    <collision>
      <geometry>
        <mesh filename="package://bipedal_robot/meshes/proximal_pitch_R_Link.STL"/>
      </geometry>
    </collision>
  </link>
  <joint name="proximal_pitch_R_Joint" type="revolute">
    <origin xyz="-0.00044 -0.09178 0.05474" rpy="-0.0 0.0 -0.0"/>
    <parent link="base_Link"/>
    <child link="proximal_pitch_R_Link"/>
    <axis xyz="-0.0 0.9961947268929313 0.0871554135479712"/>
    <limit lower="-3.141592653589793" upper="2.600540585471551" effort="150.0" velocity="18.3"/>
  </joint>
  <link name="proximal_roll_R_Link">
    <inertial>
      <origin xyz="0.03124 -0.00035 -0.08414" rpy="-0.0 0.0 -0.0"/>
      <mass value="1.74"/>
      <inertia ixx="0.00476933" ixy="1.172e-05" ixz="3.271e-05" iyy="0.00545584" iyz="2.946e-05" izz="0.00305316"/>
    </inertial>
    <visual>
      <geometry>
        <mesh filename="package://bipedal_robot/meshes/proximal_roll_R_Link.STL"/>
      </geometry>
      <material name="grey">
        <color rgba="1 1 1 1"/>
      </material>
    </visual>
    <collision>
      <geometry>
        <mesh filename="package://bipedal_robot/meshes/proximal_roll_R_Link.STL"/>
      </geometry>
    </collision>
  </link>
  <joint name="proximal_roll_R_Joint" type="revolute">
    <origin xyz="-0.032 -0.0758 -0.00663" rpy="-0.0 0.0 -0.0"/>
    <parent link="proximal_pitch_R_Link"/>
    <child link="proximal_roll_R_Link"/>
    <axis xyz="1.0 0.0 0.0"/>
    <limit lower="-3.193952531149623" upper="0.2617993877991494" effort="150.0" velocity="18.3"/>
  </joint>
  <link name="proximal_yaw_R_Link">
    <inertial>
      <origin xyz="-0.00254 -0.00155 -0.10742" rpy="-0.0 0.0 -0.0"/>
      <mass value="1.65"/>
      <inertia ixx="0.01554314" ixy="3.32e-06" ixz="0.00024639" iyy="0.01485362" iyz="-7.569e-05" izz="0.00378004"/>
    </inertial>
    <visual>
      <geometry>
        <mesh filename="package://bipedal_robot/meshes/proximal_yaw_R_Link.STL"/>
      </geometry>
      <material name="grey">
        <color rgba="1 1 1 1"/>
      </material>
    </visual>
    <collision>
      <geometry>
        <mesh filename="package://bipedal_robot/meshes/proximal_yaw_R_Link.STL"/>
      </geometry>
    </collision>
  </link>
  <joint name="proximal_yaw_R_Joint" type="revolute">
    <origin xyz="0.032 -0.0 -0.1374" rpy="-0.0 0.0 -0.0"/>
    <parent link="proximal_roll_R_Link"/>
    <child link="proximal_yaw_R_Link"/>
    <axis xyz="0.0 0.0 1.0"/>
    <limit lower="-1.4835298641951802" upper="3.6651914291880923" effort="60.0" velocity="22.52"/>
  </joint>
  <link name="knee_R_Link">
    <inertial>
      <origin xyz="-0.00204 0.02449 -0.12995" rpy="-0.0 0.0 -0.0"/>
      <mass value="4.66"/>
      <inertia ixx="0.11057056" ixy="-7.11e-06" ixz="-0.0010003" iyy="0.11286353" iyz="-0.00158987" izz="0.00620343"/>
    </inertial>
    <visual>
      <geometry>
        <mesh filename="package://bipedal_robot/meshes/knee_R_Link.STL"/>
      </geometry>
      <material name="grey">
        <color rgba="1 1 1 1"/>
      </material>
    </visual>
    <collision>
      <geometry>
        <mesh filename="package://bipedal_robot/meshes/knee_R_Link.STL"/>
      </geometry>
    </collision>
  </link>
  <joint name="knee_R_Joint" type="revolute">
    <origin xyz="0.004 -0.032 -0.2126" rpy="-0.0 0.0 -0.0"/>
    <parent link="proximal_yaw_R_Link"/>
    <child link="knee_R_Link"/>
    <axis xyz="0.0 1.0 0.0"/>
    <limit lower="-2.6179938779914944" upper="0.2617993877991494" effort="150.0" velocity="18.3"/>
  </joint>
  <link name="wheel_R_Link">
    <inertial>
      <origin xyz="0.00048 -0.00484 0.0003" rpy="-0.0 0.0 -0.0"/>
      <mass value="0.91"/>
      <inertia ixx="0.00256223" ixy="-7.6e-07" ixz="-2.292e-05" iyy="0.00490844" iyz="-4.2e-07" izz="0.00259234"/>
    </inertial>
    <visual>
      <geometry>
        <mesh filename="package://bipedal_robot/meshes/wheel_R_Link.STL"/>
      </geometry>
      <material name="grey">
        <color rgba="1 1 1 1"/>
      </material>
    </visual>
    <collision>
      <origin rpy="1.5707963267948966 0 0" xyz="0 -0.003 0"/>
      <geometry>
          <cylinder length="0.045" radius="0.1"/>
      </geometry>
    </collision>
  </link>
  <joint name="wheel_R_Joint" type="revolute">
    <origin xyz="-0.004 -0.013 -0.35" rpy="-0.0 0.0 -0.0"/>
    <parent link="knee_R_Link"/>
    <child link="wheel_R_Link"/>
    <axis xyz="0.0 1.0 0.0"/>
    <limit lower="-1745329.2519943295" upper="1745329.2519943295" effort="22.0" velocity="41.89"/>
  </joint>

  <!-- Camera --> 
  <link name="d435_Link">
    <inertial>
      <mass value="0.001"/>
      <inertia ixx="1e-07" ixy="0.0" ixz="0.0" iyy="1e-07" iyz="0.0" izz="1e-07"/>
    </inertial>
    <visual>
      <geometry>
        <box size="0.005 0.005 0.005"/>
      </geometry>
    </visual>
  </link>
  <joint name="d435_Joint" type="fixed">
    <origin xyz="0.0968 0.01759 -0.00409" rpy="0 2.7227 0"/>
    <parent link="base_Link"/>
    <child link="d435_Link"/>
  </joint>
  
  <link name="d435_optical_frame">
    <inertial>
      <mass value="0.001"/>
      <inertia ixx="1e-07" ixy="0.0" ixz="0.0" iyy="1e-07" iyz="0.0" izz="1e-07"/>
    </inertial>
  </link>
  <joint name="d435_optical_Joint" type="fixed">
    <origin rpy="-1.5707963267948966 0 -1.5707963267948966" xyz="0 0 0"/>
    <parent link="d435_Link"/>
    <child link="d435_optical_frame"/>
  </joint>

  <!-- transition Link -->
  <link name="transition_Link">
    <inertial>
      <origin xyz="-0.111727 0.000317 0.014516" rpy="0.0 0.0 0.0"/>
      <mass value="1.117"/>
      <inertia ixx="0.002739303" ixy="6.6427e-05" ixz="0.000914255" iyy="0.006871988" iyz="-2.0809e-05" izz="0.007888835"/>
    </inertial>
    <visual>
      <geometry>
        <mesh filename="package://bipedal_robot/meshes/transition_Link.STL"/>
      </geometry>
      <material name="grey">
        <color rgba="1 1 1 1"/>
      </material>
    </visual>
    <collision>
      <geometry>
        <mesh filename="package://bipedal_robot/meshes/transition_Link_collision.STL"/>
      </geometry>
    </collision>
  </link>
  <joint name="transition_Joint" type="fixed">
    <origin xyz="0.01 0.0 0.26915" rpy="0.0 0.0 0.0"/>
    <parent link="base_Link"/>
    <child link="transition_Link"/>
  </joint>
  <link name="arm_base_Link">
    <inertial>
      <origin xyz="-0.004736412 2.5683e-05 0.041451518" rpy="0.0 0.0 0.0"/>
      <mass value="1.02"/>
      <inertia ixx="0.00267433" ixy="-7.3e-07" ixz="-0.00017389" iyy="0.00282612" iyz="4e-07" izz="0.00089624"/>
    </inertial>
    <visual>
      <geometry>
        <mesh filename="package://bipedal_robot/meshes/arm_base_Link.STL"/>
      </geometry>
      <material name="grey">
        <color rgba="1 1 1 1"/>
      </material>
    </visual>
    <collision>
      <geometry>
        <mesh filename="package://bipedal_robot/meshes/arm_base_Link.STL"/>
      </geometry>
    </collision>
  </link>
  <joint name="arm_base_Joint" type="fixed">
    <origin xyz="0.006 0.0 0.0" rpy="0.0 0.0 0.0"/>
    <parent link="transition_Link"/>
    <child link="arm_base_Link"/>
  </joint>
  <link name="arm1_Link">
    <inertial>
      <origin xyz="0.00053 -0.00039 -0.00315" rpy="0.0 0.0 0.0"/>
      <mass value="0.71"/>
      <inertia ixx="0.00050027" ixy="7.8e-07" ixz="6.26e-06" iyy="0.00040879" iyz="4.62e-06" izz="0.00045802"/>
    </inertial>
    <visual>
      <geometry>
        <mesh filename="package://bipedal_robot/meshes/arm1_Link.STL"/>
      </geometry>
      <material name="grey">
        <color rgba="1 1 1 1"/>
      </material>
    </visual>
    <collision>
      <geometry>
        <mesh filename="package://bipedal_robot/meshes/arm1_Link.STL"/>
      </geometry>
    </collision>
  </link>
  <joint name="arm1_Joint" type="revolute">
    <origin xyz="0.0 0.0 0.123" rpy="0.0 0.0 3.1415926"/>
    <parent link="arm_base_Link"/>
    <child link="arm1_Link"/>
    <axis xyz="0.0 0.0 1.0"/>
    <limit lower="-2.6179938081783245" upper="2.6179938081783245" effort="100.0" velocity="5.0"/>
  </joint>
  <link name="arm2_Link">
    <inertial>
      <origin xyz="0.21856 -0.00859 0.00227" rpy="0.0 0.0 0.0"/>
      <mass value="1.16"/>
      <inertia ixx="0.00111915" ixy="0.00182916" ixz="0.00019233" iyy="0.06763251" iyz="7.67e-06" izz="0.067559"/>
    </inertial>
    <visual>
      <geometry>
        <mesh filename="package://bipedal_robot/meshes/arm2_Link.STL"/>
      </geometry>
      <material name="grey">
        <color rgba="1 1 1 1"/>
      </material>
    </visual>
    <collision>
      <geometry>
        <mesh filename="package://bipedal_robot/meshes/arm2_Link_collision1.STL"/>
      </geometry>
    </collision>
    <collision>
      <geometry>
        <mesh filename="package://bipedal_robot/meshes/arm2_Link_collision2.STL"/>
      </geometry>
    </collision>
  </link>
  <joint name="arm2_Joint" type="revolute">
    <origin xyz="0.0 0.0 0.0" rpy="-1.5707963 -3.005806 -3.1415926"/>
    <parent link="arm1_Link"/>
    <child link="arm2_Link"/>
    <axis xyz="0.0 0.0 1.0"/>
    <limit lower="0.0" upper="3.141592601229916" effort="100.0" velocity="5.0"/>
  </joint>
  <link name="arm3_Link">
    <inertial>
      <origin xyz="0.2014 -0.00418 -0.00141" rpy="0.0 0.0 0.0"/>
      <mass value="0.67"/>
      <inertia ixx="0.00033471" ixy="0.00026891" ixz="0.00013918" iyy="0.03360411" iyz="5.2e-07" izz="0.03356941"/>
    </inertial>
    <visual>
      <geometry>
        <mesh filename="package://bipedal_robot/meshes/arm3_Link.STL"/>
      </geometry>
      <material name="grey">
        <color rgba="1 1 1 1"/>
      </material>
    </visual>
    <collision>
      <geometry>
        <mesh filename="package://bipedal_robot/meshes/arm3_Link_collision1.STL"/>
      </geometry>
    </collision>
    <collision>
      <geometry>
        <mesh filename="package://bipedal_robot/meshes/arm3_Link_collision2.STL"/>
      </geometry>
    </collision>
  </link>
  <joint name="arm3_Joint" type="revolute">
    <origin xyz="0.28503 0.0 0.0" rpy="0.0 0.0 2.8380798"/>
    <parent link="arm2_Link"/>
    <child link="arm3_Link"/>
    <axis xyz="0.0 0.0 1.0"/>
    <limit lower="-2.967059693483775" upper="0.0" effort="100.0" velocity="5.0"/>
  </joint>
  <link name="arm4_Link">
    <inertial>
      <origin xyz="0.059 -0.05831 0.002" rpy="0.0 0.0 0.0"/>
      <mass value="0.39"/>
      <inertia ixx="0.00120173" ixy="0.00138165" ixz="1.187e-05" iyy="0.00209324" iyz="2.17e-06" izz="0.00307814"/>
    </inertial>
    <visual>
      <geometry>
        <mesh filename="package://bipedal_robot/meshes/arm4_Link.STL"/>
      </geometry>
      <material name="grey">
        <color rgba="1 1 1 1"/>
      </material>
    </visual>
    <collision>
      <geometry>
        <mesh filename="package://bipedal_robot/meshes/arm4_Link_collision1.STL"/>
      </geometry>
    </collision>
    <collision>
      <geometry>
        <mesh filename="package://bipedal_robot/meshes/arm4_Link_collision2.STL"/>
      </geometry>
    </collision>
  </link>
  <joint name="arm4_Joint" type="revolute">
    <origin xyz="0.27364 0.0 0.0" rpy="0.0 0.0 0.0806342"/>
    <parent link="arm3_Link"/>
    <child link="arm4_Link"/>
    <axis xyz="0.0 0.0 1.0"/>
    <limit lower="-1.5533429993683683" upper="1.5533429993683683" effort="100.0" velocity="5.0"/>
  </joint>
  <link name="arm5_Link">
    <inertial>
      <origin xyz="5e-05 -0.01282 -0.00429" rpy="0.0 0.0 0.0"/>
      <mass value="0.35"/>
      <inertia ixx="0.0002266" ixy="1.9e-07" ixz="5e-08" iyy="0.0001774" iyz="8.5e-07" izz="0.00019425"/>
    </inertial>
    <visual>
      <geometry>
        <mesh filename="package://bipedal_robot/meshes/arm5_Link.STL"/>
      </geometry>
      <material name="grey">
        <color rgba="1 1 1 1"/>
      </material>
    </visual>
    <collision>
      <geometry>
        <mesh filename="package://bipedal_robot/meshes/arm5_Link.STL"/>
      </geometry>
    </collision>
  </link>
  <joint name="arm5_Joint" type="revolute">
    <origin xyz="0.07466 0.0 0.0" rpy="-1.5707963 1.5707963 0.0"/>
    <parent link="arm4_Link"/>
    <child link="arm5_Link"/>
    <axis xyz="0.0 0.0 1.0"/>
    <limit lower="-1.5533429993683683" upper="1.5533429993683683" effort="100.0" velocity="5.0"/>
  </joint>
  <link name="arm6_Link">
    <inertial>
      <origin xyz="0.0 0.0 -0.0035" rpy="0.0 0.0 0.0"/>
      <mass value="0.007"/>
      <inertia ixx="0.00152112" ixy="2.02e-06" ixz="2.61e-06" iyy="0.00138626" iyz="2e-08" izz="0.00031152"/>
    </inertial>
    <visual>
      <geometry>
        <mesh filename="package://bipedal_robot/meshes/arm6_Link.STL"/>
      </geometry>
      <material name="grey">
        <color rgba="1 1 1 1"/>
      </material>
    </visual>
  </link>
  <joint name="arm6_Joint" type="revolute">
    <origin xyz="0.0 -0.035 0.0" rpy="1.5707963 0.0 0.0"/>
    <parent link="arm5_Link"/>
    <child link="arm6_Link"/>
    <axis xyz="0.0 0.0 1.0"/>
    <limit lower="-2.0943951023931953" upper="2.0943951023931953" effort="100.0" velocity="5.0"/>
  </joint>
  <link name="gripper_base_Link">
    <inertial>
      <origin xyz="-0.000183807 8.0503e-05 0.032143669" rpy="0.0 0.0 0.0"/>
      <mass value="0.45"/>
      <inertia ixx="0.00092934" ixy="3.4e-07" ixz="-7.38e-06" iyy="0.00071447" iyz="5e-08" izz="0.00039442"/>
    </inertial>
    <visual>
      <geometry>
        <mesh filename="package://bipedal_robot/meshes/gripper_base_Link.STL"/>
      </geometry>
      <material name="grey">
        <color rgba="1 1 1 1"/>
      </material>
    </visual>
    <collision>
      <geometry>
        <mesh filename="package://bipedal_robot/meshes/gripper_base_Link_collision1.STL"/>
      </geometry>
    </collision>
    <collision>
      <geometry>
        <mesh filename="package://bipedal_robot/meshes/gripper_base_Link_collision2.STL"/>
      </geometry>
    </collision>
  </link>
  <joint name="gripper_base_Joint" type="fixed">
    <origin xyz="0.0 0.0 0.0" rpy="0.0 0.0 1.5707963"/>
    <parent link="arm6_Link"/>
    <child link="gripper_base_Link"/>
  </joint>
  <link name="gripper1_Link">
    <inertial>
      <origin xyz="0.000651232 -0.049192987 0.009722588" rpy="0.0 0.0 0.0"/>
      <mass value="0.025"/>
      <inertia ixx="7.371e-05" ixy="-1.13e-06" ixz="2.1e-07" iyy="7.81e-06" iyz="-1.372e-05" izz="7.47e-05"/>
    </inertial>
    <visual>
      <geometry>
        <mesh filename="package://bipedal_robot/meshes/gripper1_Link.STL"/>
      </geometry>
      <material name="grey">
        <color rgba="1 1 1 1"/>
      </material>
    </visual>
    <collision>
      <geometry>
        <mesh filename="package://bipedal_robot/meshes/gripper1_Link.STL"/>
      </geometry>
    </collision>
  </link>
  <joint name="gripper1_Joint" type="prismatic">
    <origin xyz="0.0 0.0 0.1358" rpy="1.5707963 0.0 0.0"/>
    <parent link="gripper_base_Link"/>
    <child link="gripper1_Link"/>
    <axis xyz="0.0 0.0 1.0"/>
    <limit lower="0.0" upper="0.050000000424915834" effort="10.0" velocity="3.0"/>
  </joint>
  <link name="gripper2_Link">
    <inertial>
      <origin xyz="0.000651232 -0.049192987 0.009722588" rpy="0.0 0.0 0.0"/>
      <mass value="0.025"/>
      <inertia ixx="7.371e-05" ixy="-1.13e-06" ixz="2.1e-07" iyy="7.81e-06" iyz="-1.372e-05" izz="7.47e-05"/>
    </inertial>
    <visual>
      <geometry>
        <mesh filename="package://bipedal_robot/meshes/gripper2_Link.STL"/>
      </geometry>
      <material name="grey">
        <color rgba="1 1 1 1"/>
      </material>
    </visual>
    <collision>
      <geometry>
        <mesh filename="package://bipedal_robot/meshes/gripper2_Link.STL"/>
      </geometry>
    </collision>
  </link>
  <joint name="gripper2_Joint" type="prismatic">
    <origin xyz="0.0 0.0 0.1358" rpy="1.5707963 0.0 -3.1415926"/>
    <parent link="gripper_base_Link"/>
    <child link="gripper2_Link"/>
    <axis xyz="-0.0 -0.0 1.0"/>
    <limit lower="-0.0" upper="0.050000000424915834" effort="10.0" velocity="3.0"/>
  </joint>

  <!-- antenna L Link -->
  <link name="antenna_L_Link">
    <inertial>
      <origin xyz="-2.7e-05 -0.028426 0.013784" rpy="0.0 0.0 0.0"/>
      <mass value="0.231"/>
      <inertia ixx="0.000424493" ixy="-1.15e-07" ixz="-1.18e-07" iyy="0.000169977" iyz="3.0807e-05" izz="0.00039175"/>
    </inertial>
    <visual>
      <geometry>
        <mesh filename="package://bipedal_robot/meshes/antenna_L_Link.STL"/>
      </geometry>
      <material name="grey">
        <color rgba="1 1 1 1"/>
      </material>
    </visual>
    <collision>
      <geometry>
        <mesh filename="package://bipedal_robot/meshes/antenna_L_Link_collision1.STL"/>
      </geometry>
    </collision>
    <collision>
      <geometry>
        <mesh filename="package://bipedal_robot/meshes/antenna_L_Link_collision2.STL"/>
      </geometry>
    </collision>
  </link>
  <joint name="antenna_L_Joint" type="fixed">
    <origin xyz="-0.0025 0.16692 0.211" rpy="0.0 0.0 0.0"/>
    <parent link="base_Link"/>
    <child link="antenna_L_Link"/>
  </joint>

  <!-- antenna R Link -->
  <link name="antenna_R_Link">
    <inertial>
      <origin xyz="2.7e-05 0.028426 0.013784" rpy="0.0 0.0 0.0"/>
      <mass value="0.231"/>
      <inertia ixx="0.000424493" ixy="-1.15e-07" ixz="1.17e-07" iyy="0.000169977" iyz="-3.0808e-05" izz="0.000391749"/>
    </inertial>
    <visual>
      <geometry>
        <mesh filename="package://bipedal_robot/meshes/antenna_R_Link.STL"/>
      </geometry>
      <material name="grey">
        <color rgba="1 1 1 1"/>
      </material>
    </visual>
    <collision>
      <geometry>
        <mesh filename="package://bipedal_robot/meshes/antenna_R_Link_collision1.STL"/>
      </geometry>
    </collision>
    <collision>
      <geometry>
        <mesh filename="package://bipedal_robot/meshes/antenna_R_Link_collision2.STL"/>
      </geometry>
    </collision>
  </link>
  <joint name="antenna_R_Joint" type="fixed">
    <origin xyz="-0.0025 -0.16692 0.211" rpy="0.0 0.0 0.0"/>
    <parent link="base_Link"/>
    <child link="antenna_R_Link"/>
  </joint>

  <!-- camera mount Link -->
  <link name="camera_mount_Link">
    <inertial>
      <origin xyz="0.002536 0.000321 -0.060392" rpy="0.0 0.0 0.0"/>
      <mass value="0.381"/>
      <inertia ixx="0.001630905" ixy="-3.911e-06" ixz="-0.000204624" iyy="0.001504517" iyz="-3.269e-06" izz="0.000548227"/>
    </inertial>
    <visual>
      <geometry>
        <mesh filename="package://bipedal_robot/meshes/camera_mount_Link.STL"/>
      </geometry>
      <material name="grey">
        <color rgba="1 1 1 1"/>
      </material>
    </visual>
    <collision>
      <geometry>
        <mesh filename="package://bipedal_robot/meshes/camera_mount_Link_collision.STL"/>
      </geometry>
    </collision>
  </link>
  <joint name="camera_mount_Joint" type="fixed">
    <origin xyz="0.18058 0.0 0.23876" rpy="0.0 0.0 0.0"/>
    <parent link="base_Link"/>
    <child link="camera_mount_Link"/>
  </joint>
  <link name="radar_Link">
    <inertial>
      <origin xyz="-4.8e-05 8.4e-05 0.03502" rpy="0.0 0.0 0.0"/>
      <mass value="0.394"/>
      <inertia ixx="0.000308871" ixy="6.27e-07" ixz="-4.96e-07" iyy="0.000308088" iyz="8.62e-07" izz="0.000305305"/>
    </inertial>
    <visual>
      <geometry>
        <mesh filename="package://bipedal_robot/meshes/radar_Link.STL"/>
      </geometry>
      <material name="grey">
        <color rgba="1 1 1 1"/>
      </material>
    </visual>
    <collision>
      <geometry>
        <mesh filename="package://bipedal_robot/meshes/radar_Link.STL"/>
      </geometry>
    </collision>
  </link>
  <joint name="radar_Joint" type="fixed">
    <origin xyz="0.0 0.0 0.0" rpy="0.0 0.0 0.0"/>
    <parent link="camera_mount_Link"/>
    <child link="radar_Link"/>
  </joint>
</robot>