<?xml version='1.0' encoding='utf-8'?>
<robot name="bipedal_robot">

  <!-- Materials -->
  <material name="grey">
    <color rgba="1 1 1 1"/>
  </material>
  <material name="white">
    <color rgba="1.0 1.0 1.0 1.0"/>
  </material>

  <material name="orange">
    <color rgba="1.0 0.423 0.039 1.0"/>
  </material>

    <!-- ros2_control plugin -->
    <gazebo>
      <plugin filename="libgazebo_ros2_control.so" name="gazebo_ros2_control">
        <parameters>$(find tron2_gazebo)/config/default_tron2.yaml</parameters>
      </plugin>
    </gazebo>
    <ros2_control name="bipedal_robotGazeboSystem" type="system">
      <hardware>
        <plugin>tron2_gazebo/Tron2HWSim</plugin>
      </hardware>
      <joint name="proximal_pitch_L_Joint">
        <command_interface name="position"/>
        <command_interface name="velocity"/>
        <command_interface name="effort"/>
        <state_interface name="position"/>
        <state_interface name="velocity"/>
        <state_interface name="effort"/>
      </joint>
      <joint name="proximal_roll_L_Joint">
        <command_interface name="position"/>
        <command_interface name="velocity"/>
        <command_interface name="effort"/>
        <state_interface name="position"/>
        <state_interface name="velocity"/>
        <state_interface name="effort"/>
      </joint>
      <joint name="proximal_yaw_L_Joint">
        <command_interface name="position"/>
        <command_interface name="velocity"/>
        <command_interface name="effort"/>
        <state_interface name="position"/>
        <state_interface name="velocity"/>
        <state_interface name="effort"/>
      </joint>
      <joint name="knee_L_Joint">
        <command_interface name="position"/>
        <command_interface name="velocity"/>
        <command_interface name="effort"/>
        <state_interface name="position"/>
        <state_interface name="velocity"/>
        <state_interface name="effort"/>
      </joint>
      <joint name="ankle_pitch_L_Joint">
        <command_interface name="position"/>
        <command_interface name="velocity"/>
        <command_interface name="effort"/>
        <state_interface name="position"/>
        <state_interface name="velocity"/>
        <state_interface name="effort"/>
      </joint>
      <joint name="proximal_pitch_R_Joint">
        <command_interface name="position"/>
        <command_interface name="velocity"/>
        <command_interface name="effort"/>
        <state_interface name="position"/>
        <state_interface name="velocity"/>
        <state_interface name="effort"/>
      </joint>
      <joint name="proximal_roll_R_Joint">
        <command_interface name="position"/>
        <command_interface name="velocity"/>
        <command_interface name="effort"/>
        <state_interface name="position"/>
        <state_interface name="velocity"/>
        <state_interface name="effort"/>
      </joint>
      <joint name="proximal_yaw_R_Joint">
        <command_interface name="position"/>
        <command_interface name="velocity"/>
        <command_interface name="effort"/>
        <state_interface name="position"/>
        <state_interface name="velocity"/>
        <state_interface name="effort"/>
      </joint>
      <joint name="knee_R_Joint">
        <command_interface name="position"/>
        <command_interface name="velocity"/>
        <command_interface name="effort"/>
        <state_interface name="position"/>
        <state_interface name="velocity"/>
        <state_interface name="effort"/>
      </joint>
      <joint name="ankle_pitch_R_Joint">
        <command_interface name="position"/>
        <command_interface name="velocity"/>
        <command_interface name="effort"/>
        <state_interface name="position"/>
        <state_interface name="velocity"/>
        <state_interface name="effort"/>
      </joint>
      <sensor name="limx_imu_sensor">
        <state_interface name="orientation.x"/>
        <state_interface name="orientation.y"/>
        <state_interface name="orientation.z"/>
        <state_interface name="orientation.w"/>
        <state_interface name="angular_velocity.x"/>
        <state_interface name="angular_velocity.y"/>
        <state_interface name="angular_velocity.z"/>
        <state_interface name="linear_acceleration.x"/>
        <state_interface name="linear_acceleration.y"/>
        <state_interface name="linear_acceleration.z"/>
      </sensor>
    </ros2_control>
    <gazebo reference="limx_imu">
      <sensor type="imu" name="limx_imu_sensor">
        <always_on>true</always_on>
        <update_rate>100</update_rate>
        <visualize>true</visualize>
        <plugin filename="libgazebo_ros_imu_sensor.so" name="imu_plugin">
          <ros>
            <namespace/>
            <remapping>~/out:=imu</remapping>
          </ros>
          <initial_orientation_as_reference>false</initial_orientation_as_reference>
        </plugin>
      </sensor>
    </gazebo>
  
    <!-- Ground truth pose plugin -->
    <gazebo>
      <plugin filename="libgazebo_ros_p3d.so" name="p3d_base_controller">
        <ros>
          <remapping>odom:=ground_truth/state</remapping>
        </ros>
        <update_rate>1000.0</update_rate>
        <body_name>base_Link</body_name>
        <frame_name>world</frame_name>
        <gaussian_noise>0.0</gaussian_noise>
        <xyz_offset>0 0 0</xyz_offset>
        <rpy_offset>0 0 0</rpy_offset>
      </plugin>
    </gazebo>
  
    <!-- IMU Link -->
    <joint name="limx_imu_joint" type="fixed">
      <origin rpy="0.0 0.0 0.0" xyz="0.0 0.0 0.0"/>
      <parent link="base_Link"/>
      <child link="limx_imu"/>
    </joint>
    <link name="limx_imu">
      <inertial>
        <mass value="0.01"/>
        <origin rpy="0 0 0" xyz="0 0 0"/>
        <inertia ixx="0.000001" ixy="0" ixz="0" iyy="0.000001" iyz="0" izz="0.000001"/>
      </inertial>
      <visual>
        <origin rpy="0 0 0" xyz="0 0 0"/>
        <geometry>
          <box size="0.015 0.015 0.004"/>
        </geometry>
        <material name="orange">
          <color rgba="1.0 0.423 0.039 1.0"/>
        </material>
      </visual>
    </link>
    <gazebo reference="limx_imu_joint">
      <disableFixedJointLumping>true</disableFixedJointLumping>
    </gazebo>

  <link name="base_Link">
    <inertial>
      <origin xyz="-0.00205 -0.0001 0.11304" rpy="0.0 0.0 0.0"/>
      <mass value="11.07"/>
      <inertia ixx="0.10445703" ixy="3.354e-05" ixz="0.00721853" iyy="0.12093021" iyz="8.419e-05" izz="0.08893163"/>
    </inertial>
    <visual>
      <geometry>
        <mesh filename="package://robot_description/tron2/SF_TRON2B/meshes/base_Link.STL"/>
      </geometry>
      <material name="grey">
        <color rgba="1 1 1 1"/>
      </material>
    </visual>
    <collision>
      <geometry>
        <mesh filename="package://robot_description/tron2/SF_TRON2B/meshes/base_Link.STL"/>
      </geometry>
    </collision>
  </link>

  <!-- proximal_pitch_L_Link -->
  <link name="proximal_pitch_L_Link">
    <inertial>
      <origin xyz="-0.00522 0.06976 -0.00608" rpy="0.0 0.0 0.0"/>
      <mass value="2.07"/>
      <inertia ixx="0.00415453" ixy="-1.4e-05" ixz="1.841e-05" iyy="0.00292229" iyz="5.196e-05" izz="0.00333339"/>
    </inertial>
    <visual>
      <geometry>
        <mesh filename="package://robot_description/tron2/SF_TRON2B/meshes/proximal_pitch_L_Link.STL"/>
      </geometry>
      <material name="grey">
        <color rgba="1 1 1 1"/>
      </material>
    </visual>
    <collision>
      <geometry>
        <mesh filename="package://robot_description/tron2/SF_TRON2B/meshes/proximal_pitch_L_Link.STL"/>
      </geometry>
    </collision>
  </link>
  <joint name="proximal_pitch_L_Joint" type="revolute">
    <origin xyz="-0.00044 0.09178 0.05474" rpy="0.0 0.0 0.0"/>
    <parent link="base_Link"/>
    <child link="proximal_pitch_L_Link"/>
    <axis xyz="0.0 0.9961947268929313 -0.0871554135479712"/>
    <limit lower="-3.141592653589793" upper="2.600540585471551" effort="150.0" velocity="18.3"/>
  </joint>
  <link name="proximal_roll_L_Link">
    <inertial>
      <origin xyz="0.03124 0.00035 -0.08414" rpy="0.0 0.0 0.0"/>
      <mass value="1.74"/>
      <inertia ixx="0.00476933" ixy="-1.172e-05" ixz="3.271e-05" iyy="0.00545584" iyz="-2.946e-05" izz="0.00305316"/>
    </inertial>
    <visual>
      <geometry>
        <mesh filename="package://robot_description/tron2/SF_TRON2B/meshes/proximal_roll_L_Link.STL"/>
      </geometry>
      <material name="grey">
        <color rgba="1 1 1 1"/>
      </material>
    </visual>
    <collision>
      <geometry>
        <mesh filename="package://robot_description/tron2/SF_TRON2B/meshes/proximal_roll_L_Link.STL"/>
      </geometry>
    </collision>
  </link>
  <joint name="proximal_roll_L_Joint" type="revolute">
    <origin xyz="-0.032 0.0758 -0.00663" rpy="0.0 0.0 0.0"/>
    <parent link="proximal_pitch_L_Link"/>
    <child link="proximal_roll_L_Link"/>
    <axis xyz="1.0 0.0 0.0"/>
    <limit lower="-0.2617993877991494" upper="3.19395248" effort="150.0" velocity="18.3"/>
  </joint>
  <link name="proximal_yaw_L_Link">
    <inertial>
      <origin xyz="-0.00276 0.00164 -0.11148" rpy="0.0 0.0 0.0"/>
      <mass value="1.56"/>
      <inertia ixx="0.01503966" ixy="-3.86e-06" ixz="0.00026664" iyy="0.01434141" iyz="6.594e-05" izz="0.00375785"/>
    </inertial>
    <visual>
      <geometry>
        <mesh filename="package://robot_description/tron2/SF_TRON2B/meshes/proximal_yaw_L_Link.STL"/>
      </geometry>
      <material name="grey">
        <color rgba="1 1 1 1"/>
      </material>
    </visual>
    <collision>
      <geometry>
        <mesh filename="package://robot_description/tron2/SF_TRON2B/meshes/proximal_yaw_L_Link.STL"/>
      </geometry>
    </collision>
  </link>
  <joint name="proximal_yaw_L_Joint" type="revolute">
    <origin xyz="0.032 0.0 -0.1374" rpy="0.0 0.0 0.0"/>
    <parent link="proximal_roll_L_Link"/>
    <child link="proximal_yaw_L_Link"/>
    <axis xyz="0.0 0.0 1.0"/>
    <limit lower="-3.6651914291880923" upper="1.4835298641951802" effort="60.0" velocity="22.52"/>
  </joint>
  <link name="knee_L_Link">
    <inertial>
      <origin xyz="-0.00217 -0.02964 -0.12834" rpy="0.0 0.0 0.0"/>
      <mass value="4.25"/>
      <inertia ixx="0.09615017" ixy="-3.745e-05" ixz="-0.00092774" iyy="0.09699427" iyz="-0.00286736" izz="0.00528618"/>
    </inertial>
    <visual>
      <geometry>
        <mesh filename="package://robot_description/tron2/SF_TRON2B/meshes/knee_L_Link.STL"/>
      </geometry>
      <material name="grey">
        <color rgba="1 1 1 1"/>
      </material>
    </visual>
    <collision>
      <geometry>
        <mesh filename="package://robot_description/tron2/SF_TRON2B/meshes/knee_L_Link.STL"/>
      </geometry>
    </collision>
  </link>
  <joint name="knee_L_Joint" type="revolute">
    <origin xyz="0.004 0.032 -0.2126" rpy="0.0 0.0 0.0"/>
    <parent link="proximal_yaw_L_Link"/>
    <child link="knee_L_Link"/>
    <axis xyz="0.0 1.0 0.0"/>
    <limit lower="-2.6179938779914944" upper="0.2617993877991494" effort="150.0" velocity="18.3"/>
  </joint>
  <link name="ankle_pitch_L_Link">
    <inertial>
      <origin xyz="-0.01525 0.03542 -0.04668" rpy="0.0 0.0 0.0"/>
      <mass value="1.02"/>
      <inertia ixx="0.0014433" ixy="3.545e-05" ixz="-0.00014515" iyy="0.00346181" iyz="6.835e-05" izz="0.00394199"/>
    </inertial>
    <visual>
      <geometry>
        <mesh filename="package://robot_description/tron2/SF_TRON2B/meshes/ankle_pitch_L_Link.STL"/>
      </geometry>
      <material name="grey">
        <color rgba="1 1 1 1"/>
      </material>
    </visual>
    <collision>
      <geometry>
        <mesh filename="package://robot_description/tron2/SF_TRON2B/meshes/ankle_pitch_L_Link.STL"/>
      </geometry>
    </collision>
  </link>
  <joint name="ankle_pitch_L_Joint" type="revolute">
    <origin xyz="-0.004 -0.06775 -0.35" rpy="0.0 0.0 0.0"/>
    <parent link="knee_L_Link"/>
    <child link="ankle_pitch_L_Link"/>
    <axis xyz="0.0 1.0 0.0"/>
    <limit lower="-1.6231562043547265" upper="1.6231562043547265" effort="60.0" velocity="22.52"/>
  </joint>

  <!-- proximal_pitch_R_Link -->
  <link name="proximal_pitch_R_Link">
    <inertial>
      <origin xyz="-0.00522 -0.06976 -0.00608" rpy="-0.0 0.0 -0.0"/>
      <mass value="2.07"/>
      <inertia ixx="0.00415453" ixy="1.4e-05" ixz="1.841e-05" iyy="0.00292229" iyz="-5.196e-05" izz="0.00333339"/>
    </inertial>
    <visual>
      <geometry>
        <mesh filename="package://robot_description/tron2/SF_TRON2B/meshes/proximal_pitch_R_Link.STL"/>
      </geometry>
      <material name="grey">
        <color rgba="1 1 1 1"/>
      </material>
    </visual>
    <collision>
      <geometry>
        <mesh filename="package://robot_description/tron2/SF_TRON2B/meshes/proximal_pitch_R_Link.STL"/>
      </geometry>
    </collision>
  </link>
  <joint name="proximal_pitch_R_Joint" type="revolute">
    <origin xyz="-0.00044 -0.09178 0.05474" rpy="0.0 0.0 0.0"/>
    <parent link="base_Link"/>
    <child link="proximal_pitch_R_Link"/>
    <axis xyz="0.0 0.9961947268929313 0.0871554135479712"/>
    <limit lower="-3.141592653589793" upper="2.600540585471551" effort="150.0" velocity="18.3"/>
  </joint>
  <link name="proximal_roll_R_Link">
    <inertial>
      <origin xyz="0.03124 -0.00035 -0.08414" rpy="-0.0 0.0 -0.0"/>
      <mass value="1.74"/>
      <inertia ixx="0.00476933" ixy="1.172e-05" ixz="3.271e-05" iyy="0.00545584" iyz="2.946e-05" izz="0.00305316"/>
    </inertial>
    <visual>
      <geometry>
        <mesh filename="package://robot_description/tron2/SF_TRON2B/meshes/proximal_roll_R_Link.STL"/>
      </geometry>
      <material name="grey">
        <color rgba="1 1 1 1"/>
      </material>
    </visual>
    <collision>
      <geometry>
        <mesh filename="package://robot_description/tron2/SF_TRON2B/meshes/proximal_roll_R_Link.STL"/>
      </geometry>
    </collision>
  </link>
  <joint name="proximal_roll_R_Joint" type="revolute">
    <origin xyz="-0.032 -0.0758 -0.00663" rpy="-0.0 0.0 -0.0"/>
    <parent link="proximal_pitch_R_Link"/>
    <child link="proximal_roll_R_Link"/>
    <axis xyz="1.0 0.0 0.0"/>
    <limit lower="-3.19395248" upper="0.2617993877991494" effort="150.0" velocity="18.3"/>
  </joint>
  <link name="proximal_yaw_R_Link">
    <inertial>
      <origin xyz="-0.00276 -0.00164 -0.11148" rpy="-0.0 0.0 -0.0"/>
      <mass value="1.56"/>
      <inertia ixx="0.01503966" ixy="3.86e-06" ixz="0.00026664" iyy="0.01434141" iyz="-6.594e-05" izz="0.00375785"/>
    </inertial>
    <visual>
      <geometry>
        <mesh filename="package://robot_description/tron2/SF_TRON2B/meshes/proximal_yaw_R_Link.STL"/>
      </geometry>
      <material name="grey">
        <color rgba="1 1 1 1"/>
      </material>
    </visual>
    <collision>
      <geometry>
        <mesh filename="package://robot_description/tron2/SF_TRON2B/meshes/proximal_yaw_R_Link.STL"/>
      </geometry>
    </collision>
  </link>
  <joint name="proximal_yaw_R_Joint" type="revolute">
    <origin xyz="0.032 -0.0 -0.1374" rpy="-0.0 0.0 -0.0"/>
    <parent link="proximal_roll_R_Link"/>
    <child link="proximal_yaw_R_Link"/>
    <axis xyz="0.0 0.0 1.0"/>
    <limit lower="-1.4835298641951802" upper="3.6651914291880923" effort="60.0" velocity="22.52"/>
  </joint>
  <link name="knee_R_Link">
    <inertial>
      <origin xyz="-0.00217 0.02964 -0.12834" rpy="-0.0 0.0 -0.0"/>
      <mass value="4.25"/>
      <inertia ixx="0.09615017" ixy="3.745e-05" ixz="-0.00092774" iyy="0.09699427" iyz="0.00286736" izz="0.00528618"/>
    </inertial>
    <visual>
      <geometry>
        <mesh filename="package://robot_description/tron2/SF_TRON2B/meshes/knee_R_Link.STL"/>
      </geometry>
      <material name="grey">
        <color rgba="1 1 1 1"/>
      </material>
    </visual>
    <collision>
      <geometry>
        <mesh filename="package://robot_description/tron2/SF_TRON2B/meshes/knee_R_Link.STL"/>
      </geometry>
    </collision>
  </link>
  <joint name="knee_R_Joint" type="revolute">
    <origin xyz="0.004 -0.032 -0.2126" rpy="-0.0 0.0 -0.0"/>
    <parent link="proximal_yaw_R_Link"/>
    <child link="knee_R_Link"/>
    <axis xyz="0.0 1.0 0.0"/>
    <limit lower="-2.6179938779914944" upper="0.2617993877991494" effort="150.0" velocity="18.3"/>
  </joint>
  <link name="ankle_pitch_R_Link">
    <inertial>
      <origin xyz="-0.01525 -0.03542 -0.04668" rpy="-0.0 0.0 -0.0"/>
      <mass value="1.02"/>
      <inertia ixx="0.0014433" ixy="-3.545e-05" ixz="-0.00014515" iyy="0.00346181" iyz="-6.835e-05" izz="0.00394199"/>
    </inertial>
    <visual>
      <geometry>
        <mesh filename="package://robot_description/tron2/SF_TRON2B/meshes/ankle_pitch_R_Link.STL"/>
      </geometry>
      <material name="grey">
        <color rgba="1 1 1 1"/>
      </material>
    </visual>
    <collision>
      <geometry>
        <mesh filename="package://robot_description/tron2/SF_TRON2B/meshes/ankle_pitch_R_Link.STL"/>
      </geometry>
    </collision>
  </link>
  <joint name="ankle_pitch_R_Joint" type="revolute">
    <origin xyz="-0.004 0.06775 -0.35" rpy="-0.0 0.0 -0.0"/>
    <parent link="knee_R_Link"/>
    <child link="ankle_pitch_R_Link"/>
    <axis xyz="0.0 1.0 0.0"/>
    <limit lower="-1.6231562043547265" upper="1.6231562043547265" effort="60.0" velocity="22.52"/>
  </joint>

  <!-- Camera -->
  <link name="d435_Link">
    <visual>
      <origin rpy="1.5707963267948966 0 1.5707963267948966" xyz="0.0 -0.0 0"/>
      <geometry>
        <box size="0.01 0.01 0.001"/>
      </geometry>
    </visual>
  </link>
  <joint name="d435_joint" type="fixed">
    <origin rpy="0.0 1.063778179 0.0" xyz="0.12213 0.01759 0.00599"/>
    <parent link="limx_imu"/>
    <child link="d435_Link"/>
  </joint>
  <joint name="d435_optical_joint" type="fixed">
    <origin rpy="-1.5707963267948966 0 -1.5707963267948966" xyz="0 0 0"/>
    <parent link="d435_Link"/>
    <child link="d435_optical_frame"/>
  </joint>
  <link name="d435_optical_frame"/>
  <gazebo reference="d435_Link">
    <sensor type="depth" name="d435_camera_sensor">
      <pose>0 0 0 0 0 0</pose>
      <update_rate>60</update_rate>
      <visualize>false</visualize>
      <camera>
        <horizontal_fov>1.5177</horizontal_fov>
        <image>
          <format>B8G8R8</format>
          <width>64</width>
          <height>48</height>
        </image>
        <clip>
          <near>0.1</near>
          <far>1.8</far>
        </clip>
      </camera>
      <plugin name="camera_controller" filename="libgazebo_ros_camera.so">
        <ros>
          <namespace>d435</namespace>
        </ros>
        <camera_name>d435_camera</camera_name>
        <frame_name>d435_optical_frame</frame_name>
        <min_depth>0.1</min_depth>
        <max_depth>1.8</max_depth>
      </plugin>
    </sensor>
  </gazebo>

  <!-- Gazebo link physics -->
  <gazebo reference="base_Link">
    <mu1>0.2</mu1>
    <mu2>0.2</mu2>
    <material>Gazebo/White</material>
  </gazebo>
  <gazebo reference="proximal_pitch_L_Link">
    <mu1>0.2</mu1>
    <mu2>0.2</mu2>
    <material>Gazebo/DarkGrey</material>
  </gazebo>
  <gazebo reference="proximal_roll_L_Link">
    <mu1>0.2</mu1>
    <mu2>0.2</mu2>
    <material>Gazebo/DarkGrey</material>
  </gazebo>
  <gazebo reference="proximal_yaw_L_Link">
    <mu1>0.2</mu1>
    <mu2>0.2</mu2>
    <material>Gazebo/White</material>
  </gazebo>
  <gazebo reference="knee_L_Link">
    <mu1>0.2</mu1>
    <mu2>0.2</mu2>
    <material>Gazebo/DarkGrey</material>
  </gazebo>
  <gazebo reference="ankle_pitch_L_Link">
    <mu1>2.0</mu1>
    <mu2>2.0</mu2>
    <material>Gazebo/DarkGrey</material>
    <self_collide>1</self_collide>
    <kp value="1000000.0"/>
    <kd value="100.0"/>
  </gazebo>
  <gazebo reference="proximal_pitch_R_Link">
    <mu1>0.2</mu1>
    <mu2>0.2</mu2>
    <material>Gazebo/DarkGrey</material>
  </gazebo>
  <gazebo reference="proximal_roll_R_Link">
    <mu1>0.2</mu1>
    <mu2>0.2</mu2>
    <material>Gazebo/DarkGrey</material>
  </gazebo>
  <gazebo reference="proximal_yaw_R_Link">
    <mu1>0.2</mu1>
    <mu2>0.2</mu2>
    <material>Gazebo/White</material>
  </gazebo>
  <gazebo reference="knee_R_Link">
    <mu1>0.2</mu1>
    <mu2>0.2</mu2>
    <material>Gazebo/DarkGrey</material>
  </gazebo>
  <gazebo reference="ankle_pitch_R_Link">
    <mu1>2.0</mu1>
    <mu2>2.0</mu2>
    <material>Gazebo/DarkGrey</material>
    <self_collide>1</self_collide>
    <kp value="1000000.0"/>
    <kd value="100.0"/>
  </gazebo>
</robot>
