<?xml version='1.0' encoding='UTF-8'?>
<mujoco model="bipedal_robot">
  <compiler angle="radian" meshdir="../meshes"/>
  <option timestep="0.001"/>
  <size njmax="5000" nconmax="1000"/>
  <default>
    <light castshadow="false" diffuse="1 1 1"/>
    <camera fovy="60"/>
    <default class="visual">
      <geom contype="0" conaffinity="0" group="1" type="mesh" rgba="0.8 0.8 0.8 1.0"/>
    </default>
    <joint damping="0.01" margin="0.0001" solreflimit="0.002 1"/>
    <geom contype="1" conaffinity="1" friction="1.0 0.3 0.3" rgba="0.5 0.6 0.7 0.5" margin="0.001" group="0" solref="0.002 1"/>
    <equality solref="0.001 1"/>
  </default>
  <visual>
    <rgba com="0 0 1 1" contactpoint="0 1 0 1" contactforce="1 0 0 1"/>
    <scale com="0.01" forcewidth="0.05" contactwidth="0.1" contactheight="0.03"/>
  </visual>
  <asset>
    <mesh name="base_Link" file="base_Link.STL"/>
    <mesh name="proximal_pitch_L_Link" file="proximal_pitch_L_Link.STL"/>
    <mesh name="proximal_roll_L_Link" file="proximal_roll_L_Link.STL"/>
    <mesh name="proximal_yaw_L_Link" file="proximal_yaw_L_Link.STL"/>
    <mesh name="knee_L_Link" file="knee_L_Link.STL"/>
    <mesh name="ankle_pitch_L_Link" file="ankle_pitch_L_Link.STL"/>
    <mesh name="proximal_pitch_R_Link" file="proximal_pitch_R_Link.STL"/>
    <mesh name="proximal_roll_R_Link" file="proximal_roll_R_Link.STL"/>
    <mesh name="proximal_yaw_R_Link" file="proximal_yaw_R_Link.STL"/>
    <mesh name="knee_R_Link" file="knee_R_Link.STL"/>
    <mesh name="ankle_pitch_R_Link" file="ankle_pitch_R_Link.STL"/>
    <texture name="skybox" type="skybox" builtin="gradient" rgb1="0.3 0.5 0.7" rgb2="0 0 0" width="512" height="3072"/>
    <texture name="plane_texture" type="2d" builtin="checker" rgb1="0.2 0.3 0.4" rgb2="0.1 0.15 0.2" width="512" height="512" mark="edge" markrgb="0.8 0.8 0.8"/>
    <material name="plane" texture="plane_texture" texrepeat="1 1" texuniform="true" reflectance="0.2"/>
  </asset>
  <worldbody>
    <geom name="floor" type="plane" material="plane" size="10 10 0.01" condim="3" conaffinity="1" contype="1"/>
    <light name="directional" directional="true" diffuse="0.6 0.6 0.6" specular="0.2 0.2 0.2" pos="0 0 4" dir="0 0 -1" castshadow="false"/>
    <camera name="track" mode="trackcom" pos="3 -3 1"/>

    <!-- base -->
    <body name="base_Link" pos="0.0 0.0 1.0">
      <inertial pos="-0.00205 -0.0001 0.11304" quat="0.696197 -0.130687 -0.132604 0.693287" mass="11.07" diaginertia="0.120931 0.107294 0.0860939"/>
      <joint type="free" stiffness="1e-09" damping="1e-08"/>
      <geom type="mesh" rgba="1 1 1 1" mesh="base_Link"/>
      <site name="base_imu" pos="0 0 0"/>

      <!-- proximal_pitch_L_Link -->
      <body name="proximal_pitch_L_Link" pos="-0.00044 0.09178 0.05474">
        <inertial pos="-0.00522 0.06976 -0.00608" quat="0.749652 0.661722 -0.011603 0.00328095" mass="2.07" diaginertia="0.00415508 0.00333952 0.00291561"/>
        <joint name="proximal_pitch_L_Joint" pos="0 0 0" axis="0 0.996195 -0.0871554" range="-3.14159 2.60054" actuatorfrcrange="-150 150"/>
        <geom type="mesh" rgba="1 1 1 1" mesh="proximal_pitch_L_Link"/>
        <body name="proximal_roll_L_Link" pos="-0.032 0.0758 -0.00663">
          <inertial pos="0.03124 0.00035 -0.08414" quat="0.700753 -0.0110253 -0.00230623 0.713315" mass="1.74" diaginertia="0.00545642 0.00476973 0.00305218"/>
          <joint name="proximal_roll_L_Joint" pos="0 0 0" axis="1 0 0" range="-0.261799 3.19395" actuatorfrcrange="-150 150"/>
          <geom type="mesh" rgba="1 1 1 1" mesh="proximal_roll_L_Link"/>
          <body name="proximal_yaw_L_Link" pos="0.032 0 -0.1374">
            <inertial pos="-0.00276 0.00164 -0.11148" quat="0.999924 0.0031357 -0.011803 -0.00159748" mass="1.56" diaginertia="0.015046 0.0143418 0.00375114"/>
            <joint name="proximal_yaw_L_Joint" pos="0 0 0" axis="0 0 1" range="-3.66519 1.48353" actuatorfrcrange="-60 60"/>
            <geom type="mesh" rgba="1 1 1 1" mesh="proximal_yaw_L_Link"/>
            <body name="knee_L_Link" pos="0.004 0.032 -0.2126">
              <inertial pos="-0.00217 -0.02964 -0.12834" quat="0.703822 -0.007364 0.0146813 0.710186" mass="4.25" diaginertia="0.0970839 0.0961596 0.00518714"/>
              <joint name="knee_L_Joint" pos="0 0 0" axis="0 1 0" range="-2.61799 0.261799" actuatorfrcrange="-150 150"/>
              <geom type="mesh" rgba="1 1 1 1" mesh="knee_L_Link"/>
              <body name="ankle_pitch_L_Link" pos="-0.004 -0.06775 -0.35">
                <inertial pos="-0.01525 0.03542 -0.04668" quat="0.0547922 0.685112 0.0383688 0.72536" mass="1.02" diaginertia="0.00395921 0.00345376 0.00143413"/>
                <joint name="ankle_pitch_L_Joint" pos="0 0 0" axis="0 1 0" range="-1.62316 1.62316" actuatorfrcrange="-60 60"/>
                <geom type="mesh" rgba="1 1 1 1" mesh="ankle_pitch_L_Link" class="visual"/>
                <geom size="0.07 0.03 0.0125" pos="-0.0144255 0.0358488 -0.0502743" type="box"/>
                <geom size="0.0025" pos="-0.119096 0.0635431 -0.07124"/>
                <geom size="0.0025" pos="-0.100494 0.00387358 -0.07124"/>
                <geom size="0.0025" pos="0.0750261 0.0116351 -0.0712375"/>
                <geom size="0.0025" pos="0.0750261 0.0627094 -0.07124"/>
                <geom size="0.0025" pos="-0.0847227 0.07905 -0.0642492"/>
                <geom size="0.0025" pos="0.0356447 0.076275 -0.0642492"/>
                <geom size="0.0025" pos="-0.0847227 -0.00771977 -0.0642492"/>
                <geom size="0.0025" pos="0.0356447 -0.00511392 -0.0642492"/>
                <geom size="0.0025" pos="-0.128058 0.0355 -0.0642461"/>
                <geom size="0.0025" pos="0.0886808 0.0355 -0.0642461"/>
              </body>
            </body>
          </body>
        </body>
      </body>

      <!-- proximal_pitch_R_Link -->
      <body name="proximal_pitch_R_Link" pos="-0.00044 -0.09178 0.05474">
        <inertial pos="-0.00522 -0.06976 -0.00608" quat="0.661722 0.749652 -0.00328095 0.011603" mass="2.07" diaginertia="0.00415508 0.00333952 0.00291561"/>
        <joint name="proximal_pitch_R_Joint" pos="0 0 0" axis="0 0.996195 0.0871554" range="-3.14159 2.60054" actuatorfrcrange="-150 150"/>
        <geom type="mesh" rgba="1 1 1 1" mesh="proximal_pitch_R_Link"/>
        <body name="proximal_roll_R_Link" pos="-0.032 -0.0758 -0.00663">
          <inertial pos="0.03124 -0.00035 -0.08414" quat="0.713315 -0.00230623 -0.0110253 0.700753" mass="1.74" diaginertia="0.00545642 0.00476973 0.00305218"/>
          <joint name="proximal_roll_R_Joint" pos="0 0 0" axis="1 0 0" range="-3.19395 0.261799" actuatorfrcrange="-150 150"/>
          <geom type="mesh" rgba="1 1 1 1" mesh="proximal_roll_R_Link"/>
          <body name="proximal_yaw_R_Link" pos="0.032 0 -0.1374">
            <inertial pos="-0.00276 -0.00164 -0.11148" quat="0.999924 -0.0031357 -0.011803 0.00159748" mass="1.56" diaginertia="0.015046 0.0143418 0.00375114"/>
            <joint name="proximal_yaw_R_Joint" pos="0 0 0" axis="0 0 1" range="-1.48353 3.66519" actuatorfrcrange="-60 60"/>
            <geom type="mesh" rgba="1 1 1 1" mesh="proximal_yaw_R_Link"/>
            <body name="knee_R_Link" pos="0.004 -0.032 -0.2126">
              <inertial pos="-0.00217 0.02964 -0.12834" quat="0.710186 0.0146813 -0.007364 0.703822" mass="4.25" diaginertia="0.0970839 0.0961596 0.00518714"/>
              <joint name="knee_R_Joint" pos="0 0 0" axis="0 1 0" range="-2.61799 0.261799" actuatorfrcrange="-150 150"/>
              <geom type="mesh" rgba="1 1 1 1" mesh="knee_R_Link"/>
              <body name="ankle_pitch_R_Link" pos="-0.004 0.06775 -0.35">
                <inertial pos="-0.01525 -0.03542 -0.04668" quat="-0.0547922 0.685112 -0.0383688 0.72536" mass="1.02" diaginertia="0.00395921 0.00345376 0.00143413"/>
                <joint name="ankle_pitch_R_Joint" pos="0 0 0" axis="0 1 0" range="-1.62316 1.62316" actuatorfrcrange="-60 60"/>
                <geom type="mesh" rgba="1 1 1 1" mesh="ankle_pitch_R_Link" class="visual"/>
                <geom size="0.07 0.03 0.0125" pos="-0.0144255 -0.0358488 -0.0502743" type="box"/>
                <geom size="0.0025" pos="-0.119096 -0.0635431 -0.07124"/>
                <geom size="0.0025" pos="-0.100494 -0.00387358 -0.07124"/>
                <geom size="0.0025" pos="0.0750261 -0.0116351 -0.0712375"/>
                <geom size="0.0025" pos="0.0750261 -0.0627094 -0.07124"/>
                <geom size="0.0025" pos="-0.0847227 -0.07905 -0.0642492"/>
                <geom size="0.0025" pos="0.0356447 -0.076275 -0.0642492"/>
                <geom size="0.0025" pos="-0.0847227 0.00771977 -0.0642492"/>
                <geom size="0.0025" pos="0.0356447 0.00511392 -0.0642492"/>
                <geom size="0.0025" pos="-0.128058 -0.0355 -0.0642461"/>
                <geom size="0.0025" pos="0.0886808 -0.0355 -0.0642461"/>
              </body>
            </body>
          </body>
        </body>
      </body>
    </body>
  </worldbody>
  <actuator>
    <motor name="proximal_pitch_L" joint="proximal_pitch_L_Joint" ctrllimited="true" ctrlrange="-150 150" gear="1"/>
    <motor name="proximal_roll_L" joint="proximal_roll_L_Joint" ctrllimited="true" ctrlrange="-150 150" gear="1"/>
    <motor name="proximal_yaw_L" joint="proximal_yaw_L_Joint" ctrllimited="true" ctrlrange="-60 60" gear="1"/>
    <motor name="knee_L" joint="knee_L_Joint" ctrllimited="true" ctrlrange="-150 150" gear="1"/>
    <motor name="ankle_pitch_L" joint="ankle_pitch_L_Joint" ctrllimited="true" ctrlrange="-60 60" gear="1"/>
    <motor name="proximal_pitch_R" joint="proximal_pitch_R_Joint" ctrllimited="true" ctrlrange="-150 150" gear="1"/>
    <motor name="proximal_roll_R" joint="proximal_roll_R_Joint" ctrllimited="true" ctrlrange="-150 150" gear="1"/>
    <motor name="proximal_yaw_R" joint="proximal_yaw_R_Joint" ctrllimited="true" ctrlrange="-60 60" gear="1"/>
    <motor name="knee_R" joint="knee_R_Joint" ctrllimited="true" ctrlrange="-150 150" gear="1"/>
    <motor name="ankle_pitch_R" joint="ankle_pitch_R_Joint" ctrllimited="true" ctrlrange="-60 60" gear="1"/>
  </actuator>
  <sensor>
    <framequat objtype="site" objname="base_imu" name="quat"/>
    <gyro site="base_imu" name="gyro"/>
    <accelerometer site="base_imu" name="acc"/>

    <jointpos joint="proximal_pitch_L_Joint" name="proximal_pitch_L_pos"/>
    <jointpos joint="proximal_roll_L_Joint" name="proximal_roll_L_pos"/>
    <jointpos joint="proximal_yaw_L_Joint" name="proximal_yaw_L_pos"/>
    <jointpos joint="knee_L_Joint" name="knee_L_pos"/>
    <jointpos joint="ankle_pitch_L_Joint" name="ankle_pitch_L_pos"/>
    <jointpos joint="proximal_pitch_R_Joint" name="proximal_pitch_R_pos"/>
    <jointpos joint="proximal_roll_R_Joint" name="proximal_roll_R_pos"/>
    <jointpos joint="proximal_yaw_R_Joint" name="proximal_yaw_R_pos"/>
    <jointpos joint="knee_R_Joint" name="knee_R_pos"/>
    <jointpos joint="ankle_pitch_R_Joint" name="ankle_pitch_R_pos"/>

    <jointvel joint="proximal_pitch_L_Joint" name="proximal_pitch_L_vel"/>
    <jointvel joint="proximal_roll_L_Joint" name="proximal_roll_L_vel"/>
    <jointvel joint="proximal_yaw_L_Joint" name="proximal_yaw_L_vel"/>
    <jointvel joint="knee_L_Joint" name="knee_L_vel"/>
    <jointvel joint="ankle_pitch_L_Joint" name="ankle_pitch_L_vel"/>
    <jointvel joint="proximal_pitch_R_Joint" name="proximal_pitch_R_vel"/>
    <jointvel joint="proximal_roll_R_Joint" name="proximal_roll_R_vel"/>
    <jointvel joint="proximal_yaw_R_Joint" name="proximal_yaw_R_vel"/>
    <jointvel joint="knee_R_Joint" name="knee_R_vel"/>
    <jointvel joint="ankle_pitch_R_Joint" name="ankle_pitch_R_vel"/>

    <jointactuatorfrc joint="proximal_pitch_L_Joint" name="proximal_pitch_L_frc"/>
    <jointactuatorfrc joint="proximal_roll_L_Joint" name="proximal_roll_L_frc"/>
    <jointactuatorfrc joint="proximal_yaw_L_Joint" name="proximal_yaw_L_frc"/>
    <jointactuatorfrc joint="knee_L_Joint" name="knee_L_frc"/>
    <jointactuatorfrc joint="ankle_pitch_L_Joint" name="ankle_pitch_L_frc"/>
    <jointactuatorfrc joint="proximal_pitch_R_Joint" name="proximal_pitch_R_frc"/>
    <jointactuatorfrc joint="proximal_roll_R_Joint" name="proximal_roll_R_frc"/>
    <jointactuatorfrc joint="proximal_yaw_R_Joint" name="proximal_yaw_R_frc"/>
    <jointactuatorfrc joint="knee_R_Joint" name="knee_R_frc"/>
    <jointactuatorfrc joint="ankle_pitch_R_Joint" name="ankle_pitch_R_frc"/>
  </sensor>
</mujoco>