<?xml version='1.0' encoding='utf-8'?>
<robot name="bipedal_robot">
  <mujoco>
    <compiler meshdir="../meshes"/>
  </mujoco>

  <!-- base -->
  <link name="base_Link">
    <inertial>
      <origin xyz="0.00385 -0.00011 0.11254" rpy="0.0 0.0 0.0"/>
      <mass value="12.57"/>
      <inertia ixx="0.11473868" ixy="-1.726e-05" ixz="0.00717502" iyy="0.13581253" iyz="8.123e-05" izz="0.10540873"/>
    </inertial>
    <visual>
      <geometry>
        <mesh filename="../meshes/base_Link.STL"/>
      </geometry>
    </visual>
    <collision>
      <geometry>
        <mesh filename="../meshes/base_Link.STL"/>
      </geometry>
    </collision>
  </link>

  <!-- base imu -->
  <link name="base_imu">
    <inertial>
      <origin xyz="0.0 0.0 0.0" rpy="0.0 0.0 0.0"/>
      <mass value="0.01"/>
      <inertia ixx="1e-06" ixy="0.0" ixz="0.0" iyy="1e-06" iyz="0.0" izz="1e-06"/>
    </inertial>
  </link>
  <joint name="base_imu_Joint" type="fixed">
    <origin xyz="0.0 0.0 0.0" rpy="0.0 0.0 0.0"/>
    <parent link="base_Link"/>
    <child link="base_imu"/>
  </joint>

  <!-- proximal pitch L Link -->
  <link name="proximal_pitch_L_Link">
    <inertial>
      <origin xyz="-0.00547 0.07014 -0.00611" rpy="0.0 0.0 0.0"/>
      <mass value="2.21"/>
      <inertia ixx="0.00438539" ixy="-1.065e-05" ixz="1.817e-05" iyy="0.00308183" iyz="5.213e-05" izz="0.00349504"/>
    </inertial>
    <visual>
      <geometry>
        <mesh filename="../meshes/proximal_pitch_L_Link.STL"/>
      </geometry>
    </visual>
    <collision>
      <geometry>
        <mesh filename="../meshes/proximal_pitch_L_Link.STL"/>
      </geometry>
    </collision>
  </link>
  <joint name="proximal_pitch_L_Joint" type="revolute">
    <origin xyz="-0.00044 0.09178 0.05474" rpy="0.0 0.0 0.0"/>
    <parent link="base_Link"/>
    <child link="proximal_pitch_L_Link"/>
    <axis xyz="0.0 0.996194726892931 -0.0871554135479712"/>
    <limit lower="-3.141592653589793" upper="2.600540585471551" effort="150.0" velocity="18.3"/>
  </joint>
  <link name="proximal_roll_L_Link">
    <inertial>
      <origin xyz="0.03124 0.00035 -0.08414" rpy="0.0 0.0 0.0"/>
      <mass value="1.74"/>
      <inertia ixx="0.00476933" ixy="-1.172e-05" ixz="3.271e-05" iyy="0.00545584" iyz="-2.946e-05" izz="0.00305316"/>
    </inertial>
    <visual>
      <geometry>
        <mesh filename="../meshes/proximal_roll_L_Link.STL"/>
      </geometry>
    </visual>
    <collision>
      <geometry>
        <mesh filename="../meshes/proximal_roll_L_Link.STL"/>
      </geometry>
    </collision>
  </link>
  <joint name="proximal_roll_L_Joint" type="revolute">
    <origin xyz="-0.032 0.0758 -0.00663" rpy="0.0 0.0 0.0"/>
    <parent link="proximal_pitch_L_Link"/>
    <child link="proximal_roll_L_Link"/>
    <axis xyz="1.0 0.0 0.0"/>
    <limit lower="-0.2617993877991494" upper="3.1939524787897455" effort="150.0" velocity="18.3"/>
  </joint>
  <link name="proximal_yaw_L_Link">
    <inertial>
      <origin xyz="-0.00254 0.00155 -0.10742" rpy="0.0 0.0 0.0"/>
      <mass value="1.65"/>
      <inertia ixx="0.01554314" ixy="-3.32e-06" ixz="0.00024639" iyy="0.01485362" iyz="7.569e-05" izz="0.00378004"/>
    </inertial>
    <visual>
      <geometry>
        <mesh filename="../meshes/proximal_yaw_L_Link.STL"/>
      </geometry>
    </visual>
    <collision>
      <geometry>
        <mesh filename="../meshes/proximal_yaw_L_Link.STL"/>
      </geometry>
    </collision>
  </link>
  <joint name="proximal_yaw_L_Joint" type="revolute">
    <origin xyz="0.032 0.0 -0.1374" rpy="0.0 0.0 0.0"/>
    <parent link="proximal_roll_L_Link"/>
    <child link="proximal_yaw_L_Link"/>
    <axis xyz="0.0 0.0 1.0"/>
    <limit lower="-3.6651914291880923" upper="1.4835298641951802" effort="60.0" velocity="22.52"/>
  </joint>
  <link name="knee_L_Link">
    <inertial>
      <origin xyz="-0.00204 -0.02953 -0.12112" rpy="0.0 0.0 0.0"/>
      <mass value="4.5"/>
      <inertia ixx="0.10084664" ixy="-3.842e-05" ixz="-0.00100642" iyy="0.10273037" iyz="-0.00292437" izz="0.00591261"/>
    </inertial>
    <visual>
      <geometry>
        <mesh filename="../meshes/knee_L_Link.STL"/>
      </geometry>
    </visual>
    <collision>
      <geometry>
        <mesh filename="../meshes/knee_L_Link.STL"/>
      </geometry>
    </collision>
  </link>
  <joint name="knee_L_Joint" type="revolute">
    <origin xyz="0.004 0.032 -0.2126" rpy="0.0 0.0 0.0"/>
    <parent link="proximal_yaw_L_Link"/>
    <child link="knee_L_Link"/>
    <axis xyz="0.0 1.0 0.0"/>
    <limit lower="-2.6179938779914944" upper="0.2617993877991494" effort="150.0" velocity="18.3"/>
  </joint>
  <link name="ankle_pitch_L_Link">
    <inertial>
      <origin xyz="-0.01525 0.03542 -0.04668" rpy="0.0 0.0 0.0"/>
      <mass value="1.02"/>
      <inertia ixx="0.0014433" ixy="3.545e-05" ixz="-0.00014515" iyy="0.00346181" iyz="6.835e-05" izz="0.00394199"/>
    </inertial>
    <visual>
      <geometry>
        <mesh filename="../meshes/ankle_pitch_L_Link.STL"/>
      </geometry>
    </visual>
    <collision>
      <origin rpy="0 0 0" xyz="-0.014425463037384678 0.035848761272903706 -0.05027431354942169"/>
      <geometry>
        <box size="0.14 0.06 0.025"/>
      </geometry>
    </collision>
    <collision>
      <origin rpy="0 0 0" xyz="-0.11909570195246066 0.06354314585176701 -0.07124"/>
      <geometry>
         <sphere radius="0.0025"/>
      </geometry>
    </collision>
    <collision>
      <origin rpy="0 0 0" xyz="-0.10049390971791083 0.0038735829813696387 -0.07124"/>
      <geometry>
         <sphere radius="0.0025"/>
      </geometry>
    </collision>
    <collision>
      <origin rpy="0 0 0" xyz="0.07502612984116563 0.011635070405830783 -0.07123754260807935"/>
      <geometry>
         <sphere radius="0.0025"/>
      </geometry>
    </collision>
    <collision>
      <origin rpy="0 0 0" xyz="0.07502612984116541 0.06270942031820081 -0.07124"/>
      <geometry>
         <sphere radius="0.0025"/>
      </geometry>
    </collision>
    <collision>
      <origin rpy="0 0 0" xyz="-0.08472274114731804 0.07904998982922917 -0.06424918850744032"/>
      <geometry>
         <sphere radius="0.0025"/>
      </geometry>
    </collision>
    <collision>
      <origin rpy="0 0 0" xyz="0.03564470406430653 0.07627499491461442 -0.06424918850744032"/>
      <geometry>
         <sphere radius="0.0025"/>
      </geometry>
    </collision>
    <collision>
      <origin rpy="0 0 0" xyz="-0.08472274114731826 -0.007719774188539752 -0.06424918850744032"/>
      <geometry>
         <sphere radius="0.0025"/>
      </geometry>
    </collision>
    <collision>
      <origin rpy="0 0 0" xyz="0.03564470406430653 -0.0051139227977490265 -0.06424918850744032"/>
      <geometry>
         <sphere radius="0.0025"/>
      </geometry>
    </collision>
    <collision>
      <origin rpy="0 0 0" xyz="-0.12805773805226417 0.0355 -0.06424607954803907"/>
      <geometry>
         <sphere radius="0.0025"/>
      </geometry>
    </collision>
    <collision>
      <origin rpy="0 0 0" xyz="0.08868077416023412 0.03550000000000009 -0.06424607954803907"/>
      <geometry>
         <sphere radius="0.0025"/>
      </geometry>
    </collision>
  </link>
  <joint name="ankle_pitch_L_Joint" type="revolute">
    <origin xyz="-0.004 -0.06775 -0.35" rpy="0.0 0.0 0.0"/>
    <parent link="knee_L_Link"/>
    <child link="ankle_pitch_L_Link"/>
    <axis xyz="0.0 1.0 0.0"/>
    <limit lower="-1.6231562043547265" upper="1.6231562043547265" effort="60.0" velocity="22.52"/>
  </joint>

  <!-- proximal pitch R Link -->
  <link name="proximal_pitch_R_Link">
    <inertial>
      <origin xyz="-0.00547 -0.07014 -0.00611" rpy="-0.0 0.0 -0.0"/>
      <mass value="2.21"/>
      <inertia ixx="0.00438539" ixy="1.065e-05" ixz="1.817e-05" iyy="0.00308183" iyz="-5.213e-05" izz="0.00349504"/>
    </inertial>
    <visual>
      <geometry>
        <mesh filename="../meshes/proximal_pitch_R_Link.STL"/>
      </geometry>
    </visual>
    <collision>
      <geometry>
        <mesh filename="../meshes/proximal_pitch_R_Link.STL"/>
      </geometry>
    </collision>
  </link>
  <joint name="proximal_pitch_R_Joint" type="revolute">
    <origin xyz="-0.00044 -0.09178 0.05474" rpy="0.0 0.0 0.0"/>
    <parent link="base_Link"/>
    <child link="proximal_pitch_R_Link"/>
    <axis xyz="0.0 0.996194726892931 0.0871554135479712"/>
    <limit lower="-3.141592653589793" upper="2.600540585471551" effort="150.0" velocity="18.3"/>
  </joint>
  <link name="proximal_roll_R_Link">
    <inertial>
      <origin xyz="0.03124 -0.00035 -0.08414" rpy="0.0 0.0 0.0"/>
      <mass value="1.74"/>
      <inertia ixx="0.00476933" ixy="1.172e-05" ixz="3.271e-05" iyy="0.00545584" iyz="2.946e-05" izz="0.00305316"/>
    </inertial>
    <visual>
      <geometry>
        <mesh filename="../meshes/proximal_roll_R_Link.STL"/>
      </geometry>
    </visual>
    <collision>
      <geometry>
        <mesh filename="../meshes/proximal_roll_R_Link.STL"/>
      </geometry>
    </collision>
  </link>
  <joint name="proximal_roll_R_Joint" type="revolute">
    <origin xyz="-0.032 -0.0758 -0.00663" rpy="0.0 0.0 0.0"/>
    <parent link="proximal_pitch_R_Link"/>
    <child link="proximal_roll_R_Link"/>
    <axis xyz="1.0 0.0 0.0"/>
    <limit lower="-3.1939524787897455" upper="0.2617993877991494" effort="150.0" velocity="18.3"/>
  </joint>
  <link name="proximal_yaw_R_Link">
    <inertial>
      <origin xyz="-0.00254 -0.00155 -0.10742" rpy="-0.0 0.0 -0.0"/>
      <mass value="1.65"/>
      <inertia ixx="0.01554314" ixy="3.32e-06" ixz="0.00024639" iyy="0.01485362" iyz="-7.569e-05" izz="0.00378004"/>
    </inertial>
    <visual>
      <geometry>
        <mesh filename="../meshes/proximal_yaw_R_Link.STL"/>
      </geometry>
    </visual>
    <collision>
      <geometry>
        <mesh filename="../meshes/proximal_yaw_R_Link.STL"/>
      </geometry>
    </collision>
  </link>
  <joint name="proximal_yaw_R_Joint" type="revolute">
    <origin xyz="0.032 -0.0 -0.1374" rpy="0.0 0.0 0.0"/>
    <parent link="proximal_roll_R_Link"/>
    <child link="proximal_yaw_R_Link"/>
    <axis xyz="0.0 0.0 1.0"/>
    <limit lower="-1.4835298641951802" upper="3.6651914291880923" effort="60.0" velocity="22.52"/>
  </joint>
  <link name="knee_R_Link">
    <inertial>
      <origin xyz="-0.00204 0.02953 -0.12112" rpy="-0.0 0.0 -0.0"/>
      <mass value="4.5"/>
      <inertia ixx="0.10084664" ixy="3.842e-05" ixz="-0.00100642" iyy="0.10273037" iyz="0.00292437" izz="0.00591261"/>
    </inertial>
    <visual>
      <geometry>
        <mesh filename="../meshes/knee_R_Link.STL"/>
      </geometry>
    </visual>
    <collision>
      <geometry>
        <mesh filename="../meshes/knee_R_Link.STL"/>
      </geometry>
    </collision>
  </link>
  <joint name="knee_R_Joint" type="revolute">
    <origin xyz="0.004 -0.032 -0.2126" rpy="0.0 0.0 0.0"/>
    <parent link="proximal_yaw_R_Link"/>
    <child link="knee_R_Link"/>
    <axis xyz="0.0 1.0 0.0"/>
    <limit lower="-2.6179938779914944" upper="0.2617993877991494" effort="150.0" velocity="18.3"/>
  </joint>
  <link name="ankle_pitch_R_Link">
    <inertial>
      <origin xyz="-0.01525 -0.03542 -0.04668" rpy="0.0 0.0 0.0"/>
      <mass value="1.02"/>
      <inertia ixx="0.0014433" ixy="-3.545e-05" ixz="-0.00014515" iyy="0.00346181" iyz="-6.835e-05" izz="0.00394199"/>
    </inertial>
    <visual>
      <geometry>
        <mesh filename="../meshes/ankle_pitch_R_Link.STL"/>
      </geometry>
    </visual>
    <collision>
      <origin rpy="0 0 0" xyz="-0.014425463037384678 -0.035848761272903706 -0.05027431354942169"/>
      <geometry>
        <box size="0.14 0.06 0.025"/>
      </geometry>
    </collision>
    <collision>
      <origin rpy="0 0 0" xyz="-0.11909570195246066 -0.06354314585176701 -0.07124"/>
      <geometry>
         <sphere radius="0.0025"/>
      </geometry>
    </collision>
    <collision>
      <origin rpy="0 0 0" xyz="-0.10049390971791083 -0.0038735829813696387 -0.07124"/>
      <geometry>
         <sphere radius="0.0025"/>
      </geometry>
    </collision>
    <collision>
      <origin rpy="0 0 0" xyz="0.07502612984116563 -0.011635070405830783 -0.07123754260807935"/>
      <geometry>
         <sphere radius="0.0025"/>
      </geometry>
    </collision>
    <collision>
      <origin rpy="0 0 0" xyz="0.07502612984116541 -0.06270942031820081 -0.07124"/>
      <geometry>
         <sphere radius="0.0025"/>
      </geometry>
    </collision>
    <collision>
      <origin rpy="0 0 0" xyz="-0.08472274114731804 -0.07904998982922917 -0.06424918850744032"/>
      <geometry>
         <sphere radius="0.0025"/>
      </geometry>
    </collision>
    <collision>
      <origin rpy="0 0 0" xyz="0.03564470406430653 -0.07627499491461442 -0.06424918850744032"/>
      <geometry>
         <sphere radius="0.0025"/>
      </geometry>
    </collision>
    <collision>
      <origin rpy="0 0 0" xyz="-0.08472274114731826 0.007719774188539752 -0.06424918850744032"/>
      <geometry>
         <sphere radius="0.0025"/>
      </geometry>
    </collision>
    <collision>
      <origin rpy="0 0 0" xyz="0.03564470406430653 0.0051139227977490265 -0.06424918850744032"/>
      <geometry>
         <sphere radius="0.0025"/>
      </geometry>
    </collision>
    <collision>
      <origin rpy="0 0 0" xyz="-0.12805773805226417 -0.0355 -0.06424607954803907"/>
      <geometry>
         <sphere radius="0.0025"/>
      </geometry>
    </collision>
    <collision>
      <origin rpy="0 0 0" xyz="0.08868077416023412 -0.03550000000000009 -0.06424607954803907"/>
      <geometry>
         <sphere radius="0.0025"/>
      </geometry>
    </collision>
  </link>
  <joint name="ankle_pitch_R_Joint" type="revolute">
    <origin xyz="-0.004 0.06775 -0.35" rpy="0.0 0.0 0.0"/>
    <parent link="knee_R_Link"/>
    <child link="ankle_pitch_R_Link"/>
    <axis xyz="0.0 1.0 0.0"/>
    <limit lower="-1.6231562043547265" upper="1.6231562043547265" effort="60.0" velocity="22.52"/>
  </joint>

  <!-- Camera --> 
  <link name="d435_Link">
    <inertial>
      <mass value="0.001"/>
      <inertia ixx="1e-07" ixy="0.0" ixz="0.0" iyy="1e-07" iyz="0.0" izz="1e-07"/>
    </inertial>
    <visual>
      <geometry>
        <box size="0.005 0.005 0.005"/>
      </geometry>
    </visual>
  </link>
  <joint name="d435_Joint" type="fixed">
    <origin xyz="0.0968 0.01759 -0.00409" rpy="0 2.7227 0"/>
    <parent link="base_Link"/>
    <child link="d435_Link"/>
  </joint>
  
  <link name="d435_optical_frame">
    <inertial>
      <mass value="0.001"/>
      <inertia ixx="1e-07" ixy="0.0" ixz="0.0" iyy="1e-07" iyz="0.0" izz="1e-07"/>
    </inertial>
  </link>
  <joint name="d435_optical_Joint" type="fixed">
    <origin rpy="-1.5707963267948966 0 -1.5707963267948966" xyz="0 0 0"/>
    <parent link="d435_Link"/>
    <child link="d435_optical_frame"/>
  </joint>
</robot>
