<mujoco model="bipedal_robot">
  <option iterations="50" timestep="0.001" solver="PGS" gravity="0 0 -9.81" />

  <compiler angle="radian" meshdir="../meshes" eulerseq="zyx" autolimits="true" />

  <default>
    <joint limited="true" damping="0.01" armature="0.01" frictionloss="0.01" />
    <geom condim="4" contype="1" conaffinity="15" friction="0.2 0.2 0.001" solref="0.001 2" />
    <motor ctrllimited="true" />
    <equality solref="0.001 2" />
    <default class="visualgeom">
      <geom material="visualgeom" condim="1" contype="0" conaffinity="0" />
    </default>
  </default>

  <asset>
    <mesh name="base_Link" content_type="model/stl" file="base_Link.STL" />
    <mesh name="proximal_pitch_L_Link" content_type="model/stl" file="proximal_pitch_L_Link.STL" />
    <mesh name="proximal_roll_L_Link" content_type="model/stl" file="proximal_roll_L_Link.STL" />
    <mesh name="proximal_yaw_L_Link" content_type="model/stl" file="proximal_yaw_L_Link.STL" />
    <mesh name="knee_L_Link" content_type="model/stl" file="knee_L_Link.STL" />
    <mesh name="wheel_L_Link" content_type="model/stl" file="wheel_L_Link.STL" />
    <mesh name="proximal_roll_R_Link" content_type="model/stl" file="proximal_roll_R_Link.STL" />
    <mesh name="proximal_pitch_R_Link" content_type="model/stl" file="proximal_pitch_R_Link.STL" />
    <mesh name="wheel_R_Link" content_type="model/stl" file="wheel_R_Link.STL" />
    <mesh name="proximal_yaw_R_Link" content_type="model/stl" file="proximal_yaw_R_Link.STL" />
    <mesh name="knee_R_Link" content_type="model/stl" file="knee_R_Link.STL" />
    <texture name="texplane" type="2d" builtin="checker" rgb1="0.2 0.3 0.4" rgb2="0.1 0.15 0.2" width="100" height="100" />
    <material name="matplane" reflectance="0." texture="texplane" texrepeat="1 1" texuniform="true" />
    <material name="visualgeom" rgba="0.5 0.9 0.2 1" />
  </asset>

  <worldbody>
    <light directional="true" diffuse="0.4 0.4 0.4" specular="0.1 0.1 0.1" pos="0 0 5.0" dir="0 0 -1" castshadow="false" />
    <light directional="true" diffuse="0.6 0.6 0.6" specular="0.2 0.2 0.2" pos="0 0 4" dir="0 0 -1" castshadow="false" />
    <geom name="ground" type="plane" pos="0 0 0" size="100 100 0.001" quat="1 0 0 0" material="matplane" condim="3" conaffinity="15" />
    <camera name="fixed" pos="0 -3.0 1.2540288435964775" xyaxes="1 0 0 0 0 1" />
    <camera name="track" mode="trackcom" pos="0 -3.0 1.2540288435964775" xyaxes="1 0 0 0 0 1" />
    <body name="root" pos="0 0 0.9" quat="1 0 0 0">
      <freejoint name="root" />
      <site name="imu" size="0.01" pos="0 0 0" />
      <geom type="mesh" rgba="1 1 1 1" mesh="base_Link" contype="1" conaffinity="0" density="0" group="1" class="visualgeom" />
      <geom type="mesh" rgba="1 1 1 1" mesh="base_Link" />
      <body name="proximal_pitch_L_Link" pos="-0.00044 0.09178 0.05474">
        <inertial pos="-0.00522 0.06976 -0.00608" quat="0.749652 0.661722 -0.011603 0.00328095" mass="2.07" diaginertia="0.00415508 0.00333952 0.00291561" />
        <joint name="proximal_pitch_L_Joint" pos="0 0 0" axis="0 0.996195 -0.0871554" range="-3.14159 2.60054" actuatorfrcrange="-150 150" />
        <geom type="mesh" rgba="1 1 1 1" mesh="proximal_pitch_L_Link" contype="1" conaffinity="0" density="0" group="1" class="visualgeom" />
        <!-- <geom type="mesh" rgba="1 1 1 1" mesh="proximal_pitch_L_Link" /> -->
        <body name="proximal_roll_L_Link" pos="-0.032 0.0758 -0.00663">
          <inertial pos="0.03124 0.00035 -0.08414" quat="0.700753 -0.0110253 -0.00230623 0.713315" mass="1.74" diaginertia="0.00545642 0.00476973 0.00305218" />
          <joint name="proximal_roll_L_Joint" pos="0 0 0" axis="1 0 0" range="-0.261799 3.19395248" actuatorfrcrange="-150 150" />
          <geom type="mesh" rgba="1 1 1 1" mesh="proximal_roll_L_Link" contype="1" conaffinity="0" density="0" group="1" class="visualgeom" />
          <!-- <geom type="mesh" rgba="1 1 1 1" mesh="proximal_roll_L_Link" /> -->
          <body name="proximal_yaw_L_Link" pos="0.032 0 -0.1374">
            <inertial pos="-0.00276 0.00164 -0.11148" quat="0.999924 0.0031357 -0.011803 -0.00159748" mass="1.56" diaginertia="0.015046 0.0143418 0.00375114" />
            <joint name="proximal_yaw_L_Joint" pos="0 0 0" axis="0 0 1" range="-3.66519 1.48353" actuatorfrcrange="-60 60" />
            <geom type="mesh" rgba="1 1 1 1" mesh="proximal_yaw_L_Link" contype="1" conaffinity="0" density="0" group="1" class="visualgeom" />
            <!-- <geom type="mesh" rgba="1 1 1 1" mesh="proximal_yaw_L_Link" /> -->
            <body name="knee_L_Link" pos="0.004 0.032 -0.2126">
              <inertial pos="-0.00217 -0.02432 -0.13739" quat="0.704746 0.00841191 -0.0019474 0.709407" mass="4.42" diaginertia="0.106565 0.105297 0.00554554" />
              <joint name="knee_L_Joint" pos="0 0 0" axis="0 1 0" range="-2.61799 0.261799" actuatorfrcrange="-150 150" />
              <geom type="mesh" rgba="1 1 1 1" mesh="knee_L_Link" contype="1" conaffinity="0" density="0" group="1" class="visualgeom" />
              <geom type="mesh" rgba="1 1 1 1" mesh="knee_L_Link" />
              <body name="wheel_L_Link" pos="-0.004 0.013 -0.35">
                <inertial pos="0.00054 0.004 0.00034" quat="0.607252 0.362393 0.362282 0.607181" mass="0.75" diaginertia="0.00446439 0.0023624 0.00231131" />
                <joint name="wheel_L_Joint" pos="0 0 0" axis="0 1 0" range="-1.74533e+06 1.74533e+06" actuatorfrcrange="-22 22" />
                <geom type="mesh" rgba="1 1 1 1" mesh="wheel_L_Link" contype="1" conaffinity="0" density="0" group="1" class="visualgeom" />
                <!-- <geom type="mesh" rgba="1 1 1 1" mesh="wheel_L_Link" /> -->
                <geom type="cylinder" size="0.1 0.0225" pos="0 0.003 0" quat="0.7071068 0.7071068 0 0" rgba="1 1 1 1" friction="2.0 0.1 0.01"/>
              </body>
            </body>
          </body>
        </body>
      </body>
      <body name="proximal_pitch_R_Link" pos="-0.00044 -0.09178 0.05474">
        <inertial pos="-0.00522 -0.06976 -0.00608" quat="0.661722 0.749652 -0.00328095 0.011603" mass="2.07" diaginertia="0.00415508 0.00333952 0.00291561" />
        <joint name="proximal_pitch_R_Joint" pos="0 0 0" axis="0 0.996195 0.0871554" range="-3.14159 2.60054" actuatorfrcrange="-150 150" />
        <geom type="mesh" rgba="1 1 1 1" mesh="proximal_pitch_R_Link" contype="1" conaffinity="0" density="0" group="1" class="visualgeom" />
        <!-- <geom type="mesh" rgba="1 1 1 1" mesh="proximal_pitch_R_Link" /> -->
        <body name="proximal_roll_R_Link" pos="-0.032 -0.0758 -0.00663">
          <inertial pos="0.03124 -0.00035 -0.08414" quat="0.713315 -0.00230623 -0.0110253 0.700753" mass="1.74" diaginertia="0.00545642 0.00476973 0.00305218" />
          <joint name="proximal_roll_R_Joint" pos="0 0 0" axis="1 0 0" range="-3.19395248 0.261799" actuatorfrcrange="-150 150" />
          <geom type="mesh" rgba="1 1 1 1" mesh="proximal_roll_R_Link" contype="1" conaffinity="0" density="0" group="1" class="visualgeom" />
          <!-- <geom type="mesh" rgba="1 1 1 1" mesh="proximal_roll_R_Link" /> -->
          <body name="proximal_yaw_R_Link" pos="0.032 0 -0.1374">
            <inertial pos="-0.00276 -0.00164 -0.11148" quat="0.999924 -0.0031357 -0.011803 0.00159748" mass="1.56" diaginertia="0.015046 0.0143418 0.00375114" />
            <joint name="proximal_yaw_R_Joint" pos="0 0 0" axis="0 0 1" range="-1.48353 3.66519" actuatorfrcrange="-60 60" />
            <geom type="mesh" rgba="1 1 1 1" mesh="proximal_yaw_R_Link" contype="1" conaffinity="0" density="0" group="1" class="visualgeom" />
            <!-- <geom type="mesh" rgba="1 1 1 1" mesh="proximal_yaw_R_Link" /> -->
            <body name="knee_R_Link" pos="0.004 -0.032 -0.2126">
              <inertial pos="-0.00217 0.02432 -0.13739" quat="0.709407 -0.0019474 0.00841191 0.704746" mass="4.42" diaginertia="0.106565 0.105297 0.00554554" />
              <joint name="knee_R_Joint" pos="0 0 0" axis="0 1 0" range="-2.61799 0.261799" actuatorfrcrange="-150 150" />
              <geom type="mesh" rgba="1 1 1 1" mesh="knee_R_Link" contype="1" conaffinity="0" density="0" group="1" class="visualgeom" />
              <geom type="mesh" rgba="1 1 1 1" mesh="knee_R_Link" />
              <body name="wheel_R_Link" pos="-0.004 -0.013 -0.35">
                <inertial pos="0.00054 -0.004 0.00034" quat="0.607181 0.362282 0.362393 0.607252" mass="0.75" diaginertia="0.00446439 0.0023624 0.00231131" />
                <joint name="wheel_R_Joint" pos="0 0 0" axis="0 1 0" range="-1.74533e+06 1.74533e+06" actuatorfrcrange="-22 22" />
                <geom type="mesh" rgba="1 1 1 1" mesh="wheel_R_Link" contype="1" conaffinity="0" density="0" group="1" class="visualgeom" />
                <!-- <geom type="mesh" rgba="1 1 1 1" mesh="wheel_R_Link" /> -->
                <geom type="cylinder" size="0.1 0.0225" pos="0 -0.003 0" quat="0.7071068 0.7071068 0 0" rgba="1 1 1 1" friction="2.0 0.1 0.01"/>
              </body>
            </body>
          </body>
        </body>
      </body>
    </body>
  </worldbody>

  <actuator>
    <motor name="proximal_pitch_L_Joint" joint="proximal_pitch_L_Joint" ctrllimited="true" ctrlrange="-150 150" gear="1" />
    <motor name="proximal_roll_L_Joint" joint="proximal_roll_L_Joint" ctrllimited="true" ctrlrange="-150 150" gear="1" />
    <motor name="proximal_yaw_L_Joint" joint="proximal_yaw_L_Joint" ctrllimited="true" ctrlrange="-60 60" gear="1" />
    <motor name="knee_L_Joint" joint="knee_L_Joint" ctrllimited="true" ctrlrange="-150 150" gear="1" />
    <motor name="wheel_L_Joint" joint="wheel_L_Joint" ctrllimited="true" ctrlrange="-22 22" gear="1" />
    <motor name="proximal_pitch_R_Joint" joint="proximal_pitch_R_Joint" ctrllimited="true" ctrlrange="-150 150" gear="1" />
    <motor name="proximal_roll_R_Joint" joint="proximal_roll_R_Joint" ctrllimited="true" ctrlrange="-150 150" gear="1" />
    <motor name="proximal_yaw_R_Joint" joint="proximal_yaw_R_Joint" ctrllimited="true" ctrlrange="-60 60" gear="1" />
    <motor name="knee_R_Joint" joint="knee_R_Joint" ctrllimited="true" ctrlrange="-150 150" gear="1" />
    <motor name="wheel_R_Joint" joint="wheel_R_Joint" ctrllimited="true" ctrlrange="-22 22" gear="1" />
  </actuator>

  <sensor>
    <actuatorpos name="proximal_pitch_L_Joint_p" actuator="proximal_pitch_L_Joint" />
    <actuatorvel name="proximal_pitch_L_Joint_v" actuator="proximal_pitch_L_Joint" />
    <actuatorfrc name="proximal_pitch_L_Joint_f" actuator="proximal_pitch_L_Joint" noise="0.001" />
    <actuatorpos name="proximal_roll_L_Joint_p" actuator="proximal_roll_L_Joint" />
    <actuatorvel name="proximal_roll_L_Joint_v" actuator="proximal_roll_L_Joint" />
    <actuatorfrc name="proximal_roll_L_Joint_f" actuator="proximal_roll_L_Joint" noise="0.001" />
    <actuatorpos name="proximal_yaw_L_Joint_p" actuator="proximal_yaw_L_Joint" />
    <actuatorvel name="proximal_yaw_L_Joint_v" actuator="proximal_yaw_L_Joint" />
    <actuatorfrc name="proximal_yaw_L_Joint_f" actuator="proximal_yaw_L_Joint" noise="0.001" />
    <actuatorpos name="knee_L_Joint_p" actuator="knee_L_Joint" />
    <actuatorvel name="knee_L_Joint_v" actuator="knee_L_Joint" />
    <actuatorfrc name="knee_L_Joint_f" actuator="knee_L_Joint" noise="0.001" />
    <actuatorpos name="wheel_L_Joint_p" actuator="wheel_L_Joint" />
    <actuatorvel name="wheel_L_Joint_v" actuator="wheel_L_Joint" />
    <actuatorfrc name="wheel_L_Joint_f" actuator="wheel_L_Joint" noise="0.001" />
    <actuatorpos name="proximal_pitch_R_Joint_p" actuator="proximal_pitch_R_Joint" />
    <actuatorvel name="proximal_pitch_R_Joint_v" actuator="proximal_pitch_R_Joint" />
    <actuatorfrc name="proximal_pitch_R_Joint_f" actuator="proximal_pitch_R_Joint" noise="0.001" />
    <actuatorpos name="proximal_roll_R_Joint_p" actuator="proximal_roll_R_Joint" />
    <actuatorvel name="proximal_roll_R_Joint_v" actuator="proximal_roll_R_Joint" />
    <actuatorfrc name="proximal_roll_R_Joint_f" actuator="proximal_roll_R_Joint" noise="0.001" />
    <actuatorpos name="proximal_yaw_R_Joint_p" actuator="proximal_yaw_R_Joint" />
    <actuatorvel name="proximal_yaw_R_Joint_v" actuator="proximal_yaw_R_Joint" />
    <actuatorfrc name="proximal_yaw_R_Joint_f" actuator="proximal_yaw_R_Joint" noise="0.001" />
    <actuatorpos name="knee_R_Joint_p" actuator="knee_R_Joint" />
    <actuatorvel name="knee_R_Joint_v" actuator="knee_R_Joint" />
    <actuatorfrc name="knee_R_Joint_f" actuator="knee_R_Joint" noise="0.001" />
    <actuatorpos name="wheel_R_Joint_p" actuator="wheel_R_Joint" />
    <actuatorvel name="wheel_R_Joint_v" actuator="wheel_R_Joint" />
    <actuatorfrc name="wheel_R_Joint_f" actuator="wheel_R_Joint" noise="0.001" />
    <framequat name="quat" objtype="site" noise="0.001" objname="imu" />
    <gyro name="gyro" site="imu" noise="0.005" cutoff="34.9" />
    <accelerometer name="acc" site="imu"/>
  </sensor>
</mujoco>